Workbook

Sheet IncomeStatement
A1: In millions, except per share data | B1: 2010Q1 | C1: 2010Q2 | D1: 2010Q3 | E1: 2010Q4 | F1: 2011Q1 | G1: 2011Q2 | H1: 2011Q3 | I1: 2011Q4 | J1: 2012Q1 | K1: 2012Q2 | L1: 2012Q3 | M1: 2012Q4 | N1: 2013Q1 | O1: 2013Q2 | P1: 2013Q3 | Q1: 2013Q4 | R1: 2014Q1 | S1: 2014Q2 | T1: 2014Q3 | U1: 2014Q4 | V1: 2015Q1 | W1: 2015Q2 | X1: 2015Q3 | Y1: 2015Q4 | Z1: 2016Q1 | AA1: 2016Q2 | AB1: 2016Q3 | AC1: 2016Q4 | AD1: 2017Q1 | AE1: 2017Q2 | AF1: 2017Q3 | AG1: 2017Q4 | AH1: 2018Q1 | AI1: 2018Q2 | AJ1: 2018Q3 | AK1: 2018Q4 | AL1: 2019Q1 | AM1: 2019Q2 | AN1: 2019Q3 | AO1: 2019Q4 | AP1: 2020Q1 | AQ1: 2020Q2 | AR1: 2020Q3 | AS1: 2020Q4 | AT1: 2021Q1 | AU1: 2021Q2 | AV1: 2021Q3 | AW1: 2021Q4 | AX1: 2022Q1 | AY1: 2022Q2 | AZ1: 2022Q3 | BA1: 2022Q4 | BB1: 2023Q1 | BC1: 2023Q2 | BD1: 2023Q3 | BE1: 2023Q4 | BF1: 2024Q1 | BG1: 2024Q2 | BH1: 2024Q3 | BI1: 2024Q4
A2: Revenues
A3: Sales by Company-operated restaurants | B3: 3803.1 | C3: 4013.4 | D3: 4246.6 | E3: 4170.2 | F3: 4152.7 | G3: 4697.4 | H3: 4855.5 | I3: 4587.2 | J3: 4432.2 | K3: 4673.5 | L3: 4838.4 | M3: 4658.4 | N3: 4445.4 | O3: 4761.4 | P3: 4923.1 | Q3: 4744.3 | R3: 4490.5 | S3: 4785.9 | T3: 4596.2 | U3: 4296.7 | V3: 3914.1 | W3: 4261.1 | X3: 4282.9 | Y3: 4030.2 | Z3: 3753.5 | AA3: 3916.6 | AB3: 3972.1 | AC3: 3652.8 | AD3: 3411.9 | AE3: 3569.6 | AF3: 3064.3 | AG3: 2673.1 | AH3: 2535.6 | AI3: 2594.9 | AJ3: 2511 | AK3: 2371.2 | AL3: 2240.5 | AM3: 2400.4 | AN3: 2416.6 | AO3: 2363.3 | AP3: 2025.8 | AQ3: 1593.7 | AR3: 2286.4 | AS3: 2233.1 | AT3: 2161.5 | AU3: 2488.7 | AV3: 2598.4 | AW3: 2538.4 | AX3: 2302.4 | AY3: 2112.8 | AZ3: 2124.8 | BA3: 3247 | BB3: 2224.3 | BC3: 2487 | BD3: 2556.2 | BE3: 2474.5 | BF3: 2355 | BG3: 2461 | BH3: 2656 | BI3: 2310
A4: Revenues from franchised restaurants | B4: 1807 | C4: 1932.1 | D4: 2058.3 | E4: 2043.9 | F4: 1958.9 | G4: 2208 | H4: 2310.8 | I4: 2235.5 | J4: 2114.4 | K4: 2242.4 | L4: 2314 | M4: 2293.7 | N4: 2159.9 | O4: 2322.4 | P4: 2400.3 | Q4: 2348.9 | R4: 2209.8 | S4: 2395.8 | T4: 2390.9 | U4: 2275.5 | V4: 2044.8 | W4: 2236.6 | X4: 2332.2 | Y4: 2311.1 | Z4: 2150.4 | AA4: 2348.4 | AB4: 2452 | AC4: 2376.1 | AD4: 2264 | AE4: 2480.1 | AF4: 2690.3 | AG4: 2667.1 | AH4: 2603.3 | AI4: 2759 | AJ4: 2858.4 | AK4: 2791.8 | AL4: 2715.1 | AM4: 2940.9 | AN4: 3014 | AO4: 2985.7 | AP4: 2608 | AQ4: 2088 | AR4: 3044.8 | AS4: 2985.2 | AT4: 2877.4 | AU4: 3306.2 | AV4: 3510.2 | AW4: 3391.2 | AX4: 3262.8 | AY4: 3526.8 | AZ4: 3671.2 | BA4: 2624.2 | BB4: 3587.5 | BC4: 3933.3 | BD4: 4047.1 | BE4: 3868.1 | BF4: 3723 | BG4: 3940 | BH4: 4094 | BI4: 3958
A5: Other Revenues | AP5: 80.6 | AQ5: 79.8 | AR5: 86.9 | AS5: 95.7 | AT5: 85.7 | AU5: 93 | AV5: 92.7 | AW5: 79.6 | AX5: 100.4 | AY5: 78.8 | AZ5: 76.1 | BA5: 95.7 | BB5: 86 | BC5: 77.2 | BD5: 88.9 | BE5: 63.9 | BF5: 91 | BG5: 89 | BH5: 124 | BI5: 119
A6: Total revenues | B6: 5610.1 | C6: 5945.5 | D6: 6304.9 | E6: 6214.1 | F6: 6111.6 | G6: 6905.4 | H6: 7166.3 | I6: 6822.7 | J6: 6546.6 | K6: 6915.9 | L6: 7152.4 | M6: 6952.1 | N6: 6605.3 | O6: 7083.8 | P6: 7323.4 | Q6: 7093.2 | R6: 6700.3 | S6: 7181.7 | T6: 6987.1 | U6: 6572.2 | V6: 5958.9 | W6: 6497.7 | X6: 6615.1 | Y6: 6341.3 | Z6: 5903.9 | AA6: 6265 | AB6: 6424.1 | AC6: 6028.9 | AD6: 5675.9 | AE6: 6049.7 | AF6: 5754.6 | AG6: 5340.2 | AH6: 5138.9 | AI6: 5353.9 | AJ6: 5369.4 | AK6: 5163 | AL6: 4955.6 | AM6: 5341.3 | AN6: 5430.6 | AO6: 5349 | AP6: 4714.4 | AQ6: 3761.5 | AR6: 5418.1 | AS6: 5314 | AT6: 5124.6 | AU6: 5887.9 | AV6: 6201.3 | AW6: 6009.2 | AX6: 5665.6 | AY6: 5718.4 | AZ6: 5872.1 | BA6: 5966.9 | BB6: 5897.8 | BC6: 6497.5 | BD6: 6692.2 | BE6: 6406.5 | BF6: 6169 | BG6: 6490 | BH6: 6873 | BI6: 6388
A7: Operating costs and expenses | B7: =SUM(B8:B13) -> 3936 | C7: =SUM(C8:C13) -> 4100.2 | D7: =SUM(D8:D13) -> 4208.4 | BI7: 0
A8: Company-operated restaurant expenses | B8: 3110.9 | C8: 3214.8 | D8: 3354 | E8: 3379.8 | F8: 3416.7 | G8: 3806.8 | H8: 3883.3 | I8: 3731.1 | J8: 3654.4 | K8: 3823.8 | L8: 3914.4 | M8: 3831.1 | N8: 3726 | O8: 3919.5 | P8: 4004.4 | Q8: 3928.7 | R8: 3767.1 | S8: 3969.8 | T8: 3874.7 | U8: 3676.7 | V8: 3354.3 | W8: 3596.3 | X8: 3607.7 | Y8: 3418.6 | Z8: 3175.3 | AA8: 3248.1 | AB8: 3239.5 | AC8: 3035.9 | AD8: 2816.4 | AE8: 2903.3 | AF8: 2479.8 | AG8: 2210.1 | AH8: 2130.9 | AI8: 2130.5 | AJ8: 2047.9 | AK8: 1956.6 | AL8: 1886.2 | AM8: 1967.1 | AN8: 1967.7 | AO8: 1939.6 | AP8: 1752.8 | AQ8: 1448.4 | AR8: 1876.3 | AS8: 1903.5 | AT8: 1817.6 | AU8: 2021 | AV8: 2108.4 | AW8: 2100 | AX8: 1959.2 | AY8: 1769.8 | AZ8: 1779.6 | BA8: 2538.4 | BB8: 1923.1 | BC8: 2091.3 | BD8: 2135 | BE8: 2074.6 | BF8: 2035 | BG8: 2074 | BH8: 2248 | BI8: 1977
A9: Franchised restaurants – occupancy expenses | B9: 339.3 | C9: 334.3 | D9: 344.4 | E9: 359.8 | F9: 354.3 | G9: 373 | H9: 376.2 | I9: 378 | J9: 374.7 | K9: 376.2 | L9: 383.4 | M9: 392.7 | N9: 395.2 | O9: 399.1 | P9: 408.4 | Q9: 421.7 | R9: 417.1 | S9: 427.6 | T9: 431.2 | U9: 421.4 | V9: 403.6 | W9: 411 | X9: 416.1 | Y9: 416.2 | Z9: 415.1 | AA9: 430.9 | AB9: 437.6 | AC9: 434.8 | AD9: 430.1 | AE9: 438 | AF9: 457.3 | AG9: 464.6 | AH9: 480.3 | AI9: 483.9 | AJ9: 499.4 | AK9: 509.7 | AL9: 533.1 | AM9: 544.7 | AN9: 559.5 | AO9: 563.3 | AP9: 554.2 | AQ9: 524.5 | AR9: 567.9 | AS9: 561.4 | AT9: 571.5 | AU9: 579.1 | AV9: 592.6 | AW9: 591.8 | AX9: 584 | AY9: 588.6 | AZ9: 589 | BA9: 573.4 | BB9: 598.3 | BC9: 618.2 | BD9: 625.4 | BE9: 633.1 | BF9: 627 | BG9: 629 | BH9: 646 | BI9: 634
A10: Other restaurant expenses | AP10: 65.5 | AQ10: 63.3 | AR10: 69.2 | AS10: 69 | AT10: 67.2 | AU10: 68.3 | AV10: 68.9 | AW10: 55.6 | AX10: 72.3 | AY10: 57.9 | AZ10: 57.4 | BA10: 72.4 | BB10: 62.8 | BC10: 57 | BD10: 68.1 | BE10: 44.1 | BF10: 68 | BG10: 69 | BH10: 104 | BI10: 98
A11: Selling, general & administrative expenses | B11: 546.3 | C11: 564.9 | D11: 556.3 | E11: 665.8 | F11: 563.6 | G11: 588 | H11: 580.9 | I11: 661.2 | J11: 592.5 | K11: 617.3 | L11: 620.9 | M11: 624.5 | N11: 596.5 | O11: 607 | P11: 554.3 | Q11: 627.8 | R11: 620.4 | S11: 629.2 | T11: 575.8 | U11: 662.5 | V11: 582.8 | W11: 592.4 | X11: 584 | Y11: 675.1 | Z11: 578 | AA11: 596.1 | AB11: 582.9 | AC11: 627.5 | AD11: 521.3 | AE11: 525.4 | AF11: 567 | AG11: 617.6 | AH11: 533.1 | AI11: 542.1 | AJ11: 515.2 | AK11: 609.8 | AL11: 499.1 | AM11: 533.1 | AN11: 543.6 | AO11: 653.6 | AP11: 589.8 | AQ11: 647 | AR11: 530.5 | AS11: 778.7 | AT11: 566.4 | AU11: 655.5 | AV11: 643.7 | AW11: 842.4 | AX11: 677 | AY11: 704.2 | AZ11: 669.7 | BA11: 657.1 | BB11: 652.6 | BC11: 662.7 | BD11: 680.2 | BE11: 821.5 | BF11: 721 | BG11: 691 | BH11: 647 | BI11: 800
A12: Impairment and other charges (credits), net | B12: 30.8 | C12: 6.8 | D12: 3.6 | E12: -12.1 | G12: 2.4 | H12: -6.6 | I12: 0.3 | L12: 6.2 | M12: 1.8 | BI12: 0
A13: Other operating (income) expense, net | B13: -91.3 | C13: -20.6 | D13: -49.9 | E13: -36.4 | F13: -48.9 | G13: -53.9 | H13: -62.2 | I13: -67.9 | J13: -39.6 | K13: -56.4 | L13: -59.7 | M13: -95.8 | N13: -61.9 | O13: -39.5 | P13: -60.4 | Q13: -85.4 | R13: -40.3 | S13: -33.9 | T13: 32.9 | U13: 59.9 | V13: 232.7 | W13: 48.7 | X13: -23 | Y13: -49 | Z13: -44.8 | AA13: 132 | AB13: 26.8 | AC13: -38.3 | AD13: -125.9 | AE13: -112.1 | AF13: -828.9 | AG13: -96.3 | AH13: -148.5 | AI13: -64.9 | AJ13: -110.8 | AK13: 87.4 | AL13: -56.8 | AM13: 22.5 | AN13: -49.5 | AO13: -100.1 | AP13: 58.5 | AQ13: 117.2 | AR13: -152.2 | AS13: -141.5 | AT13: -179.4 | AU13: -127.1 | AV13: -198.8 | AW13: 22.3 | AX13: 60.5 | AY13: 886.1 | AZ13: 12.5 | BA13: -1442.1 | BB13: 128.6 | BC13: -35.8 | BD13: -24.8 | BE13: 31 | BF13: -17 | BG13: 107 | BH13: 39 | BI13: 10
A14: Total operating costs and expenses | B14: 3936 | C14: 4100.2 | D14: 4208.4 | E14: 4356.9 | F14: 4285.7 | G14: 4716.3 | H14: 4771.6 | I14: 4702.7 | J14: 4582 | K14: 4760.9 | L14: 4865.2 | M14: 4754.3 | N14: 4655.8 | O14: 4886.1 | P14: 4906.7 | Q14: 4892.8 | R14: 4764.3 | S14: 4992.7 | T14: 4914.6 | U14: 4820.5 | V14: 4573.4 | W14: 4648.4 | X14: 4584.8 | Y14: 4460.9 | Z14: 4123.6 | AA14: 4407.1 | AB14: 4286.8 | AC14: 4059.9 | AD14: 3641.9 | AE14: 3754.6 | AF14: 2675.2 | AG14: 3196 | AH14: 2995.8 | AI14: 3091.6 | AJ14: 2951.7 | AK14: 3163.5 | AL14: 2861.6 | AM14: 3067.4 | AN14: 3021.3 | AO14: 3056.4 | AP14: 3020.8 | AQ14: 2800.4 | AR14: 2891.7 | AS14: 3171.1 | AT14: 2843.3 | AU14: 3196.8 | AV14: 3214.8 | AW14: 3612.1 | AX14: 3353 | AY14: 4006.6 | AZ14: 3108.2 | BA14: 2399.2 | BB14: 3365.4 | BC14: 3393.4 | BD14: 3483.9 | BE14: 3604.3 | BF14: 3433 | BG14: 3570 | BH14: 3685 | BI14: 3520
A15: Operating income | B15: 1674.1 | C15: 1845.3 | D15: 2096.5 | E15: 1857.2 | F15: 1825.9 | G15: 2189.1 | H15: 2394.7 | I15: 2120 | J15: 1964.6 | K15: 2155 | L15: 2287.2 | M15: 2197.8 | N15: 1949.5 | O15: 2197.7 | P15: 2416.7 | Q15: 2200.4 | R15: 1936 | S15: 2189 | T15: 2072.5 | U15: 1751.7 | V15: 1385.5 | W15: 1849.3 | X15: 2030.3 | Y15: 1880.4 | Z15: 1780.3 | AA15: 1857.9 | AB15: 2137.3 | AC15: 1969 | AD15: 2034 | AE15: 2295.1 | AF15: 3079.4 | AG15: 2144.2 | AH15: 2143.1 | AI15: 2262.3 | AJ15: 2417.7 | AK15: 1999.5 | AL15: 2094 | AM15: 2273.9 | AN15: 2409.3 | AO15: 2292.6 | AP15: 1693.6 | AQ15: 961.1 | AR15: 2526.4 | AS15: 2142.9 | AT15: 2281.3 | AU15: 2691.1 | AV15: 2986.5 | AW15: 2397.1 | AX15: 2312.6 | AY15: 1711.8 | AZ15: 2763.9 | BA15: 3567.7 | BB15: 2532.4 | BC15: 3104.1 | BD15: 3208.3 | BE15: 2802.2 | BF15: 2736 | BG15: 2920 | BH15: 3188 | BI15: 2868
A16: Interest expense | B16: 111 | C16: 108.1 | D16: 114.8 | E16: 117 | F16: 120.1 | G16: 121.8 | H16: 124 | I16: 126.9 | J16: 128.9 | K16: 130 | L16: 128.1 | M16: 129.6 | N16: 128.1 | O16: 129.8 | P16: 130.5 | Q16: 133.5 | R16: 135.5 | S16: 137.9 | T16: 149.3 | U16: 147.8 | V16: 147.3 | W16: 149.2 | X16: 160.9 | Y16: 180.9 | Z16: 218.3 | AA16: 223.9 | AB16: 221.4 | AC16: 221.2 | AD16: 218.6 | AE16: 230.9 | AF16: 236.7 | AG16: 235.1 | AH16: 236.8 | AI16: 240.2 | AJ16: 250.1 | AK16: 254.1 | AL16: 274.1 | AM16: 284.2 | AN16: 280.6 | AO16: 283 | AP16: 280 | AQ16: 319.1 | AR16: 310.1 | AS16: 308.8 | AT16: 300 | AU16: 296.5 | AV16: 293.7 | AW16: 295.8 | AX16: 287.3 | AY16: 290.6 | AZ16: 306.2 | BA16: 301.9 | BB16: 329.7 | BC16: 330.2 | BD16: 340.7 | BE16: 360.4 | BF16: 372 | BG16: 373 | BH16: 381 | BI16: 380
A17: Nonoperating (income) expense, net | B17: 6.2 | C17: 1.9 | D17: 7.2 | E17: 6.6 | F17: 6.9 | G17: 0.9 | H17: 7.5 | I17: 9.4 | J17: -11.8 | K17: 15.1 | L17: 5.5 | M17: 0.2 | N17: 4.6 | O17: 8 | P17: 13.6 | Q17: 11.7 | R17: 17.2 | S17: -20.4 | T17: 2.1 | U17: 7.8 | V17: -15.9 | W17: -12.3 | X17: -9 | Y17: -11.3 | Z17: -14.4 | AA17: -16.2 | AB17: 11.4 | AC17: 12.9 | AD17: 7.9 | AE17: 2.8 | AF17: 23.2 | AG17: 24 | AH17: 18.4 | AI17: 4 | AJ17: 8.9 | AK17: -6 | AL17: -11.4 | AM17: -18.1 | AN17: -23.5 | AO17: -17.2 | AP17: -31.3 | AQ17: -6.7 | AR17: -0.8 | AS17: 3.8 | AT17: 28.6 | AU17: 18.6 | AV17: 1.4 | AW17: -6.6 | AX17: 484.1 | AY17: 12.1 | AZ17: -78.5 | BA17: -375.7 | BB17: -64.3 | BC17: -42.8 | BD17: -55.9 | BE17: -73 | BF17: -45 | BG17: -9 | BH17: -36 | BI17: -49
A18: Gain on sale of investment | BI18: 0
A19: Income before provision for income taxes | B19: 1556.9 | C19: 1735.3 | D19: 1974.5 | E19: 1733.6 | F19: 1698.9 | G19: 2066.4 | H19: 2263.2 | I19: 1983.7 | J19: 1847.5 | K19: 2009.9 | L19: 2153.6 | M19: 2068 | N19: 1816.8 | O19: 2059.9 | P19: 2272.6 | Q19: 2055.2 | R19: 1783.3 | S19: 2071.5 | T19: 1921.1 | U19: 1596.1 | V19: 1254.1 | W19: 1712.4 | X19: 1878.4 | Y19: 1710.8 | Z19: 1576.4 | AA19: 1650.2 | AB19: 1904.5 | AC19: 1734.9 | AD19: 1807.5 | AE19: 2061.4 | AF19: 2819.5 | AG19: 1885.1 | AH19: 1887.9 | AI19: 2018.1 | AJ19: 2158.7 | AK19: 1751.4 | AL19: 1831.3 | AM19: 2007.8 | AN19: 2152.2 | AO19: 2026.8 | AP19: 1444.9 | AQ19: 648.7 | AR19: 2217.1 | AS19: 1830.3 | AT19: 1952.7 | AU19: 2376 | AV19: 2691.4 | AW19: 2107.9 | AX19: 1541.2 | AY19: 1409.1 | AZ19: 2536.2 | BA19: 3641.5 | BB19: 2267 | BC19: 2816.7 | BD19: 2923.5 | BE19: 2514.8 | BF19: 2409 | BG19: 2555 | BH19: 2843 | BI19: 2538
A20: Provision for income taxes | B20: 467.1 | C20: 509.5 | D20: 586.1 | E20: 491.3 | F20: 489.9 | G20: 656.2 | H20: 755.9 | I20: 607.1 | J20: 580.8 | K20: 662.9 | L20: 698.6 | M20: 671.9 | N20: 546.6 | O20: 663.4 | P20: 750.4 | Q20: 658.2 | R20: 578.5 | S20: 684.4 | T20: 852.7 | U20: 498.6 | V20: 442.6 | W20: 510 | X20: 569.2 | Y20: 504.6 | Z20: 477.8 | AA20: 557.3 | AB20: 629.1 | AC20: 515.3 | AD20: 592.7 | AE20: 666.3 | AF20: 935.8 | AG20: 1186.4 | AH20: 512.5 | AI20: 521.8 | AJ20: 521.4 | AK20: 336.1 | AL20: 502.9 | AM20: 490.9 | AN20: 544.3 | AO20: 454.6 | AP20: 338 | AQ20: 164.9 | AR20: 454.5 | AS20: 452.6 | AT20: 415.5 | AU20: 156.7 | AV20: 541.5 | AW20: 469.3 | AX20: 436.8 | AY20: 221.1 | AZ20: 554.6 | BA20: 370.5 | BB20: 464.7 | BC20: 506.3 | BD20: 606.4 | BE20: 475.6 | BF20: 479 | BG20: 533 | BH20: 588 | BI20: 521
A21: Net income | B21: 1089.8 | C21: 1225.8 | D21: 1388.4 | E21: 1242.3 | F21: 1209 | G21: 1410.2 | H21: 1507.3 | I21: 1376.6 | J21: 1266.7 | K21: 1347 | L21: 1455 | M21: 1396.1 | N21: 1270.2 | O21: 1396.5 | P21: 1522.2 | Q21: 1397 | R21: 1204.8 | S21: 1387.1 | T21: 1068.4 | U21: 1097.5 | V21: 811.5 | W21: 1202.4 | X21: 1309.2 | Y21: 1206.2 | Z21: 1098.6 | AA21: 1092.9 | AB21: 1275.4 | AC21: 1219.6 | AD21: 1214.8 | AE21: 1395.1 | AF21: 1883.7 | AG21: 698.7 | AH21: 1375.4 | AI21: 1496.3 | AJ21: 1637.3 | AK21: 1415.3 | AL21: 1328.4 | AM21: 1516.9 | AN21: 1607.9 | AO21: 1572.2 | AP21: 1106.9 | AQ21: 483.8 | AR21: 1762.6 | AS21: 1377.7 | AT21: 1537.2 | AU21: 2219.3 | AV21: 2149.9 | AW21: 1638.6 | AX21: 1104.4 | AY21: 1188 | AZ21: 1981.6 | BA21: 3271 | BB21: 1802.3 | BC21: 2310.4 | BD21: 2317.1 | BE21: 2039.2 | BF21: 1929 | BG21: 2022 | BH21: 2255 | BI21: 2017

Sheet IncomeStatement_T
A1: YearQuarter | B1: Total revenues | C1: 1_Sales by Company-operated restaurants | D1: 2_Revenues from franchised restaurants | E1: 3_Other Revenues | F1: Total operating costs and expenses | G1: 1_Company-operated restaurant expenses | H1: 2_Franchised restaurants – occupancy expenses | I1: 3_Other restaurant expenses | J1: 4_Selling, general & administrative expenses | K1: 5_Impairment and other charges (credits), net | L1: 6_Other operating (income) expense, net | M1: Operating income | N1: 1_Interest expense | O1: 2_Nonoperating (income) expense, net | P1: Income before provision for income taxes | Q1: Provision for income taxes | R1: Net income
A2: 2010Q1 | B2: 5610.1 | C2: 3803.1 | D2: 1807 | F2: 3936 | G2: 3110.9 | H2: 339.3 | J2: 546.3 | K2: 30.8 | L2: -91.3 | M2: 1674.1 | N2: 111 | O2: 6.2 | P2: 1556.9 | Q2: 467.1 | R2: 1089.8
A3: 2010Q2 | B3: 5945.5 | C3: 4013.4 | D3: 1932.1 | F3: 4100.2 | G3: 3214.8 | H3: 334.3 | J3: 564.9 | K3: 6.8 | L3: -20.6 | M3: 1845.3 | N3: 108.1 | O3: 1.9 | P3: 1735.3 | Q3: 509.5 | R3: 1225.8
A4: 2010Q3 | B4: 6304.9 | C4: 4246.6 | D4: 2058.3 | F4: 4208.4 | G4: 3354 | H4: 344.4 | J4: 556.3 | K4: 3.6 | L4: -49.9 | M4: 2096.5 | N4: 114.8 | O4: 7.2 | P4: 1974.5 | Q4: 586.1 | R4: 1388.4
A5: 2010Q4 | B5: 6214.1 | C5: 4170.2 | D5: 2043.9 | F5: 4356.9 | G5: 3379.8 | H5: 359.8 | J5: 665.8 | K5: -12.1 | L5: -36.4 | M5: 1857.2 | N5: 117 | O5: 6.6 | P5: 1733.6 | Q5: 491.3 | R5: 1242.3
A6: 2011Q1 | B6: 6111.6 | C6: 4152.7 | D6: 1958.9 | F6: 4285.7 | G6: 3416.7 | H6: 354.3 | J6: 563.6 | L6: -48.9 | M6: 1825.9 | N6: 120.1 | O6: 6.9 | P6: 1698.9 | Q6: 489.9 | R6: 1209
A7: 2011Q2 | B7: 6905.4 | C7: 4697.4 | D7: 2208 | F7: 4716.3 | G7: 3806.8 | H7: 373 | J7: 588 | K7: 2.4 | L7: -53.9 | M7: 2189.1 | N7: 121.8 | O7: 0.9 | P7: 2066.4 | Q7: 656.2 | R7: 1410.2
A8: 2011Q3 | B8: 7166.3 | C8: 4855.5 | D8: 2310.8 | F8: 4771.6 | G8: 3883.3 | H8: 376.2 | J8: 580.9 | K8: -6.6 | L8: -62.2 | M8: 2394.7 | N8: 124 | O8: 7.5 | P8: 2263.2 | Q8: 755.9 | R8: 1507.3
A9: 2011Q4 | B9: 6822.7 | C9: 4587.2 | D9: 2235.5 | F9: 4702.7 | G9: 3731.1 | H9: 378 | J9: 661.2 | K9: 0.3 | L9: -67.9 | M9: 2120 | N9: 126.9 | O9: 9.4 | P9: 1983.7 | Q9: 607.1 | R9: 1376.6
A10: 2012Q1 | B10: 6546.6 | C10: 4432.2 | D10: 2114.4 | F10: 4582 | G10: 3654.4 | H10: 374.7 | J10: 592.5 | L10: -39.6 | M10: 1964.6 | N10: 128.9 | O10: -11.8 | P10: 1847.5 | Q10: 580.8 | R10: 1266.7
A11: 2012Q2 | B11: 6915.9 | C11: 4673.5 | D11: 2242.4 | F11: 4760.9 | G11: 3823.8 | H11: 376.2 | J11: 617.3 | L11: -56.4 | M11: 2155 | N11: 130 | O11: 15.1 | P11: 2009.9 | Q11: 662.9 | R11: 1347
A12: 2012Q3 | B12: 7152.4 | C12: 4838.4 | D12: 2314 | F12: 4865.2 | G12: 3914.4 | H12: 383.4 | J12: 620.9 | K12: 6.2 | L12: -59.7 | M12: 2287.2 | N12: 128.1 | O12: 5.5 | P12: 2153.6 | Q12: 698.6 | R12: 1455
A13: 2012Q4 | B13: 6952.1 | C13: 4658.4 | D13: 2293.7 | F13: 4754.3 | G13: 3831.1 | H13: 392.7 | J13: 624.5 | K13: 1.8 | L13: -95.8 | M13: 2197.8 | N13: 129.6 | O13: 0.2 | P13: 2068 | Q13: 671.9 | R13: 1396.1
A14: 2013Q1 | B14: 6605.3 | C14: 4445.4 | D14: 2159.9 | F14: 4655.8 | G14: 3726 | H14: 395.2 | J14: 596.5 | L14: -61.9 | M14: 1949.5 | N14: 128.1 | O14: 4.6 | P14: 1816.8 | Q14: 546.6 | R14: 1270.2
A15: 2013Q2 | B15: 7083.8 | C15: 4761.4 | D15: 2322.4 | F15: 4886.1 | G15: 3919.5 | H15: 399.1 | J15: 607 | L15: -39.5 | M15: 2197.7 | N15: 129.8 | O15: 8 | P15: 2059.9 | Q15: 663.4 | R15: 1396.5
A16: 2013Q3 | B16: 7323.4 | C16: 4923.1 | D16: 2400.3 | F16: 4906.7 | G16: 4004.4 | H16: 408.4 | J16: 554.3 | L16: -60.4 | M16: 2416.7 | N16: 130.5 | O16: 13.6 | P16: 2272.6 | Q16: 750.4 | R16: 1522.2
A17: 2013Q4 | B17: 7093.2 | C17: 4744.3 | D17: 2348.9 | F17: 4892.8 | G17: 3928.7 | H17: 421.7 | J17: 627.8 | L17: -85.4 | M17: 2200.4 | N17: 133.5 | O17: 11.7 | P17: 2055.2 | Q17: 658.2 | R17: 1397
A18: 2014Q1 | B18: 6700.3 | C18: 4490.5 | D18: 2209.8 | F18: 4764.3 | G18: 3767.1 | H18: 417.1 | J18: 620.4 | L18: -40.3 | M18: 1936 | N18: 135.5 | O18: 17.2 | P18: 1783.3 | Q18: 578.5 | R18: 1204.8
A19: 2014Q2 | B19: 7181.7 | C19: 4785.9 | D19: 2395.8 | F19: 4992.7 | G19: 3969.8 | H19: 427.6 | J19: 629.2 | L19: -33.9 | M19: 2189 | N19: 137.9 | O19: -20.4 | P19: 2071.5 | Q19: 684.4 | R19: 1387.1
A20: 2014Q3 | B20: 6987.1 | C20: 4596.2 | D20: 2390.9 | F20: 4914.6 | G20: 3874.7 | H20: 431.2 | J20: 575.8 | L20: 32.9 | M20: 2072.5 | N20: 149.3 | O20: 2.1 | P20: 1921.1 | Q20: 852.7 | R20: 1068.4
A21: 2014Q4 | B21: 6572.2 | C21: 4296.7 | D21: 2275.5 | F21: 4820.5 | G21: 3676.7 | H21: 421.4 | J21: 662.5 | L21: 59.9 | M21: 1751.7 | N21: 147.8 | O21: 7.8 | P21: 1596.1 | Q21: 498.6 | R21: 1097.5
A22: 2015Q1 | B22: 5958.9 | C22: 3914.1 | D22: 2044.8 | F22: 4573.4 | G22: 3354.3 | H22: 403.6 | J22: 582.8 | L22: 232.7 | M22: 1385.5 | N22: 147.3 | O22: -15.9 | P22: 1254.1 | Q22: 442.6 | R22: 811.5
A23: 2015Q2 | B23: 6497.7 | C23: 4261.1 | D23: 2236.6 | F23: 4648.4 | G23: 3596.3 | H23: 411 | J23: 592.4 | L23: 48.7 | M23: 1849.3 | N23: 149.2 | O23: -12.3 | P23: 1712.4 | Q23: 510 | R23: 1202.4
A24: 2015Q3 | B24: 6615.1 | C24: 4282.9 | D24: 2332.2 | F24: 4584.8 | G24: 3607.7 | H24: 416.1 | J24: 584 | L24: -23 | M24: 2030.3 | N24: 160.9 | O24: -9 | P24: 1878.4 | Q24: 569.2 | R24: 1309.2
A25: 2015Q4 | B25: 6341.3 | C25: 4030.2 | D25: 2311.1 | F25: 4460.9 | G25: 3418.6 | H25: 416.2 | J25: 675.1 | L25: -49 | M25: 1880.4 | N25: 180.9 | O25: -11.3 | P25: 1710.8 | Q25: 504.6 | R25: 1206.2
... A41: 2019Q4 | B41: 5349 | C41: 2363.3 | D41: 2985.7 | F41: 3056.4 | G41: 1939.6 | H41: 563.3 | J41: 653.6 | L41: -100.1 | M41: 2292.6 | N41: 283 | O41: -17.2 | P41: 2026.8 | Q41: 454.6 | R41: 1572.2
A42: 2020Q1 | B42: 4714.4 | C42: 2025.8 | D42: 2608 | E42: 80.6 | F42: 3020.8 | G42: 1752.8 | H42: 554.2 | I42: 65.5 | J42: 589.8 | L42: 58.5 | M42: 1693.6 | N42: 280 | O42: -31.3 | P42: 1444.9 | Q42: 338 | R42: 1106.9
A43: 2020Q2 | B43: 3761.5 | C43: 1593.7 | D43: 2088 | E43: 79.8 | F43: 2800.4 | G43: 1448.4 | H43: 524.5 | I43: 63.3 | J43: 647 | L43: 117.2 | M43: 961.1 | N43: 319.1 | O43: -6.7 | P43: 648.7 | Q43: 164.9 | R43: 483.8
A44: 2020Q3 | B44: 5418.1 | C44: 2286.4 | D44: 3044.8 | E44: 86.9 | F44: 2891.7 | G44: 1876.3 | H44: 567.9 | I44: 69.2 | J44: 530.5 | L44: -152.2 | M44: 2526.4 | N44: 310.1 | O44: -0.8 | P44: 2217.1 | Q44: 454.5 | R44: 1762.6
A45: 2020Q4 | B45: 5314 | C45: 2233.1 | D45: 2985.2 | E45: 95.7 | F45: 3171.1 | G45: 1903.5 | H45: 561.4 | I45: 69 | J45: 778.7 | L45: -141.5 | M45: 2142.9 | N45: 308.8 | O45: 3.8 | P45: 1830.3 | Q45: 452.6 | R45: 1377.7
A46: 2021Q1 | B46: 5124.6 | C46: 2161.5 | D46: 2877.4 | E46: 85.7 | F46: 2843.3 | G46: 1817.6 | H46: 571.5 | I46: 67.2 | J46: 566.4 | L46: -179.4 | M46: 2281.3 | N46: 300 | O46: 28.6 | P46: 1952.7 | Q46: 415.5 | R46: 1537.2
A47: 2021Q2 | B47: 5887.9 | C47: 2488.7 | D47: 3306.2 | E47: 93 | F47: 3196.8 | G47: 2021 | H47: 579.1 | I47: 68.3 | J47: 655.5 | L47: -127.1 | M47: 2691.1 | N47: 296.5 | O47: 18.6 | P47: 2376 | Q47: 156.7 | R47: 2219.3
A48: 2021Q3 | B48: 6201.3 | C48: 2598.4 | D48: 3510.2 | E48: 92.7 | F48: 3214.8 | G48: 2108.4 | H48: 592.6 | I48: 68.9 | J48: 643.7 | L48: -198.8 | M48: 2986.5 | N48: 293.7 | O48: 1.4 | P48: 2691.4 | Q48: 541.5 | R48: 2149.9
A49: 2021Q4 | B49: 6009.2 | C49: 2538.4 | D49: 3391.2 | E49: 79.6 | F49: 3612.1 | G49: 2100 | H49: 591.8 | I49: 55.6 | J49: 842.4 | L49: 22.3 | M49: 2397.1 | N49: 295.8 | O49: -6.6 | P49: 2107.9 | Q49: 469.3 | R49: 1638.6
A50: 2022Q1 | B50: 5665.6 | C50: 2302.4 | D50: 3262.8 | E50: 100.4 | F50: 3353 | G50: 1959.2 | H50: 584 | I50: 72.3 | J50: 677 | L50: 60.5 | M50: 2312.6 | N50: 287.3 | O50: 484.1 | P50: 1541.2 | Q50: 436.8 | R50: 1104.4
A51: 2022Q2 | B51: 5718.4 | C51: 2112.8 | D51: 3526.8 | E51: 78.8 | F51: 4006.6 | G51: 1769.8 | H51: 588.6 | I51: 57.9 | J51: 704.2 | L51: 886.1 | M51: 1711.8 | N51: 290.6 | O51: 12.1 | P51: 1409.1 | Q51: 221.1 | R51: 1188
A52: 2022Q3 | B52: 5872.1 | C52: 2124.8 | D52: 3671.2 | E52: 76.1 | F52: 3108.2 | G52: 1779.6 | H52: 589 | I52: 57.4 | J52: 669.7 | L52: 12.5 | M52: 2763.9 | N52: 306.2 | O52: -78.5 | P52: 2536.2 | Q52: 554.6 | R52: 1981.6
A53: 2022Q4 | B53: 5966.9 | C53: 3247 | D53: 2624.2 | E53: 95.7 | F53: 2399.2 | G53: 2538.4 | H53: 573.4 | I53: 72.4 | J53: 657.1 | L53: -1442.1 | M53: 3567.7 | N53: 301.9 | O53: -375.7 | P53: 3641.5 | Q53: 370.5 | R53: 3271
... A61: 2024Q4 | B61: 6388 | C61: 2310 | D61: 3958 | E61: 119 | F61: 3520 | G61: 1977 | H61: 634 | I61: 98 | J61: 800 | L61: 10 | M61: 2868 | N61: 380 | O61: -49 | P61: 2538 | Q61: 521 | R61: 2017

Sheet RevenueModel
N1: Alpha | S1: Alpha | X1: Alpha | Y1: Beta | AE1: Alpha | AF1: Beta | AG1: Gamma
N2: 0 | S2: 0.59751445 | X2: 0.5975012 | Y2: 0 | AE2: 0.59871826 | AF2: 0 | AG2: 0.48727397
B3: Quarter | C3: Total Revenue | D3: MA3_YoY | E3: Error | F3: MAE | G3: MSE | H3: MAPE | I3: MA4_Consecutive | J3: Error | K3: MAE | L3: MSE | M3: MAPE | N3: MA_Hybrid | O3: Error | P3: MAE | Q3: MSE | R3: MAPE | S3: SES | T3: Error | U3: MAE | V3: MSE | W3: MAPE | X3: Level | Y3: Trend | Z3: Holt | AA3: Error | AB3: MAE | AC3: MSE | AD3: MAPE | AE3: Level | AF3: Trend | AG3: Seasonal | AH3: Holt-Winters | AI3: Error | AJ3: MAE | AK3: MSE | AL3: MAPE | AM3: ARIMA | AN3: Error | AO3: MAE | AP3: MSE | AQ3: MAPE
B4: 2007Q1 | C4: 5292.7
B5: 2007Q2 | C5: 5839.4
B6: 2007Q3 | C6: 5900.9
B7: 2007Q4 | C7: 5753.6
B8: 2008Q1 | C8: 5614.8
B9: 2008Q2 | C9: 6075.3
B10: 2008Q3 | C10: 6267.3
B11: 2008Q4 | C11: 5565
B12: 2009Q1 | C12: 5077.4 | AG12: =C12/$AE$15 -> 0.8929377
B13: 2009Q2 | C13: 5647.2 | AG13: =C13/$AE$15 -> 0.99314566
B14: 2009Q3 | C14: 6046.7 | AG14: =C14/$AE$15 -> 1.0634038
B15: 2009Q4 | C15: 5973.4 | X15: =C15 -> 5973.4 | Y15: =(C67-C15)/COUNT(C15:C67) -> -0.12264151 | AE15: =AVERAGE(C12:C15) -> 5686.175 | AF15: 0 | AG15: =C15/$AE$15 -> 1.0505129
A16: Training | B16: 2010Q1 | C16: 5610.1 | D16: =AVERAGE(C4,C8,C12) -> 5328.3 | E16: =$C16-D16 -> 281.8 | F16: =ABS(E16) -> 281.8 | G16: =E16^2 -> 79411.24 | H16: =F16/$C16 -> 0.050230834 | I16: =AVERAGE(C12:C15) -> 5686.175 | J16: =$C16-I16 -> -76.075 | K16: =ABS(J16) -> 76.075 | L16: =J16^2 -> 5787.4056 | M16: =K16/$C16 -> 0.013560364 | N16: =D16*$N$2+I16*(1-$N$2) -> 5686.175 | O16: =$C16-N16 -> -76.075 | P16: =ABS(O16) -> 76.075 | Q16: =O16^2 -> 5787.4056 | R16: =P16/$C16 -> 0.013560364 | S16: =C15 -> 5973.4 | T16: =$C16-S16 -> -363.3 | U16: =ABS(T16) -> 363.3 | V16: =T16^2 -> 131986.89 | W16: =U16/$C16 -> 0.064758204 | X16: =C16*$X$2+(1-$X$2)*(X15+Y15) -> 5756.2785 | Y16: =$Y$2*(X16-X15)+(1-$Y$2)*Y15 -> -0.12264151 | Z16: =X15+Y15 -> 5973.2774 | AA16: =$C16-Z16 -> -363.17736 | AB16: =ABS(AA16) -> 363.17736 | AC16: =AA16^2 -> 131897.79 | AD16: =AB16/$C16 -> 0.064736343 | AE16: =$AE$2*(C16/AG12)+(1-$AE$2)*(AE15+AF15) -> 6043.3525 | AF16: =$AF$2*(AE16-AE15)+(1-$AF$2)*AF15 -> 0 | AG16: =$AG$2*(C16/AE16)+(1-$AG$2)*AG12 -> 0.91017333 | AH16: =(AE15+AF15)*AG12 -> 5077.4 | AI16: =$C16-AH16 -> 532.7 | AJ16: =ABS(AI16) -> 532.7 | AK16: =AI16^2 -> 283769.29 | AL16: =AJ16/$C16 -> 0.094953744 | AM16: 5894.6077 | AN16: =$C16-AM16 -> -284.50769 | AO16: =ABS(AN16) -> 284.50769 | AP16: =AN16^2 -> 80944.625 | AQ16: =AO16/$C16 -> 0.050713479
B17: 2010Q2 | C17: 5945.5 | D17: =AVERAGE(C5,C9,C13) -> 5853.9667 | E17: =$C17-D17 -> 91.533333 | F17: =ABS(E17) -> 91.533333 | G17: =E17^2 -> 8378.3511 | H17: =F17/$C17 -> 0.015395397 | I17: =AVERAGE(C13:C16) -> 5819.35 | J17: =$C17-I17 -> 126.15 | K17: =ABS(J17) -> 126.15 | L17: =J17^2 -> 15913.822 | M17: =K17/$C17 -> 0.021217728 | N17: =D17*$N$2+I17*(1-$N$2) -> 5819.35 | O17: =$C17-N17 -> 126.15 | P17: =ABS(O17) -> 126.15 | Q17: =O17^2 -> 15913.822 | R17: =P17/$C17 -> 0.021217728 | S17: =C16*$S$2+S16*(1-$S$2) -> 5756.323 | T17: =$C17-S17 -> 189.177 | U17: =ABS(T17) -> 189.177 | V17: =T17^2 -> 35787.938 | W17: =U17/$C17 -> 0.031818518 | X17: =C17*$X$2+(1-$X$2)*(X16+Y16) -> 5869.2892 | Y17: =$Y$2*(X17-X16)+(1-$Y$2)*Y16 -> -0.12264151 | Z17: =X16+Y16 -> 5756.1558 | AA17: =$C17-Z17 -> 189.34419 | AB17: =ABS(AA17) -> 189.34419 | AC17: =AA17^2 -> 35851.223 | AD17: =AB17/$C17 -> 0.031846639 | AE17: =$AE$2*(C17/AG13)+(1-$AE$2)*(AE16+AF16) -> 6009.3341 | AF17: =$AF$2*(AE17-AE16)+(1-$AF$2)*AF16 -> 0 | AG17: =$AG$2*(C17/AE17)+(1-$AG$2)*AG13 -> 0.99130954 | AH17: =(AE16+AF16)*AG13 -> 6001.9292 | AI17: =$C17-AH17 -> -56.429239 | AJ17: =ABS(AI17) -> 56.429239 | AK17: =AI17^2 -> 3184.259 | AL17: =AJ17/$C17 -> 0.0094910839 | AM17: 5918.3522 | AN17: =$C17-AM17 -> 27.147771 | AO17: =ABS(AN17) -> 27.147771 | AP17: =AN17^2 -> 737.00148 | AQ17: =AO17/$C17 -> 0.004566104
B18: 2010Q3 | C18: 6304.9 | D18: =AVERAGE(C6,C10,C14) -> 6071.6333 | E18: =$C18-D18 -> 233.26667 | F18: =ABS(E18) -> 233.26667 | G18: =E18^2 -> 54413.338 | H18: =F18/$C18 -> 0.036997679 | I18: =AVERAGE(C14:C17) -> 5893.925 | J18: =$C18-I18 -> 410.975 | K18: =ABS(J18) -> 410.975 | L18: =J18^2 -> 168900.45 | M18: =K18/$C18 -> 0.065183429 | N18: =D18*$N$2+I18*(1-$N$2) -> 5893.925 | O18: =$C18-N18 -> 410.975 | P18: =ABS(O18) -> 410.975 | Q18: =O18^2 -> 168900.45 | R18: =P18/$C18 -> 0.065183429 | S18: =C17*$S$2+S17*(1-$S$2) -> 5869.359 | T18: =$C18-S18 -> 435.54101 | U18: =ABS(T18) -> 435.54101 | V18: =T18^2 -> 189695.97 | W18: =U18/$C18 -> 0.069079765 | X18: =C18*$X$2+(1-$X$2)*(X17+Y17) -> 6129.5178 | Y18: =$Y$2*(X18-X17)+(1-$Y$2)*Y17 -> -0.12264151 | Z18: =X17+Y17 -> 5869.1665 | AA18: =$C18-Z18 -> 435.73345 | AB18: =ABS(AA18) -> 435.73345 | AC18: =AA18^2 -> 189863.64 | AD18: =AB18/$C18 -> 0.069110287 | AE18: =$AE$2*(C18/AG14)+(1-$AE$2)*(AE17+AF17) -> 5961.2248 | AF18: =$AF$2*(AE18-AE17)+(1-$AF$2)*AF17 -> 0 | AG18: =$AG$2*(C18/AE18)+(1-$AG$2)*AG14 -> 1.060601 | AH18: =(AE17+AF17)*AG14 -> 6390.3486 | AI18: =$C18-AH18 -> -85.448574 | AJ18: =ABS(AI18) -> 85.448574 | AK18: =AI18^2 -> 7301.4588 | AL18: =AJ18/$C18 -> 0.013552725 | AM18: 6330.2626 | AN18: =$C18-AM18 -> -25.362647 | AO18: =ABS(AN18) -> 25.362647 | AP18: =AN18^2 -> 643.26388 | AQ18: =AO18/$C18 -> 0.0040226883
B19: 2010Q4 | C19: 6214.1 | D19: =AVERAGE(C7,C11,C15) -> 5764 | E19: =$C19-D19 -> 450.1 | F19: =ABS(E19) -> 450.1 | G19: =E19^2 -> 202590.01 | H19: =F19/$C19 -> 0.07243205 | I19: =AVERAGE(C15:C18) -> 5958.475 | J19: =$C19-I19 -> 255.625 | K19: =ABS(J19) -> 255.625 | L19: =J19^2 -> 65344.141 | M19: =K19/$C19 -> 0.041136287 | N19: =D19*$N$2+I19*(1-$N$2) -> 5958.475 | O19: =$C19-N19 -> 255.625 | P19: =ABS(O19) -> 255.625 | Q19: =O19^2 -> 65344.141 | R19: =P19/$C19 -> 0.041136287 | S19: =C18*$S$2+S18*(1-$S$2) -> 6129.601 | T19: =$C19-S19 -> 84.498961 | U19: =ABS(T19) -> 84.498961 | V19: =T19^2 -> 7140.0744 | W19: =U19/$C19 -> 0.01359794 | X19: =C19*$X$2+(1-$X$2)*(X18+Y18) -> 6180.0064 | Y19: =$Y$2*(X19-X18)+(1-$Y$2)*Y18 -> -0.12264151 | Z19: =X18+Y18 -> 6129.3952 | AA19: =$C19-Z19 -> 84.704832 | AB19: =ABS(AA19) -> 84.704832 | AC19: =AA19^2 -> 7174.9085 | AD19: =AB19/$C19 -> 0.01363107 | AE19: =$AE$2*(C19/AG15)+(1-$AE$2)*(AE18+AF18) -> 5933.7295 | AF19: =$AF$2*(AE19-AE18)+(1-$AF$2)*AF18 -> 0 | AG19: =$AG$2*(C19/AE19)+(1-$AG$2)*AG15 -> 1.0489231 | AH19: =(AE18+AF18)*AG15 -> 6262.3433 | AI19: =$C19-AH19 -> -48.24331 | AJ19: =ABS(AI19) -> 48.24331 | AK19: =AI19^2 -> 2327.4169 | AL19: =AJ19/$C19 -> 0.0077635232 | AM19: 6237.8082 | AN19: =$C19-AM19 -> -23.70815 | AO19: =ABS(AN19) -> 23.70815 | AP19: =AN19^2 -> 562.07639 | AQ19: =AO19/$C19 -> 0.0038152186
B20: 2011Q1 | C20: 6111.6 | D20: =AVERAGE(C8,C12,C16) -> 5434.1 | E20: =$C20-D20 -> 677.5 | F20: =ABS(E20) -> 677.5 | G20: =E20^2 -> 459006.25 | H20: =F20/$C20 -> 0.11085477 | I20: =AVERAGE(C16:C19) -> 6018.65 | J20: =$C20-I20 -> 92.95 | K20: =ABS(J20) -> 92.95 | L20: =J20^2 -> 8639.7025 | M20: =K20/$C20 -> 0.015208783 | N20: =D20*$N$2+I20*(1-$N$2) -> 6018.65 | O20: =$C20-N20 -> 92.95 | P20: =ABS(O20) -> 92.95 | Q20: =O20^2 -> 8639.7025 | R20: =P20/$C20 -> 0.015208783 | S20: =C19*$S$2+S19*(1-$S$2) -> 6180.0904 | T20: =$C20-S20 -> -68.49039 | U20: =ABS(T20) -> 68.49039 | V20: =T20^2 -> 4690.9335 | W20: =U20/$C20 -> 0.011206622 | X20: =C20*$X$2+(1-$X$2)*(X19+Y19) -> 6139.0841 | Y20: =$Y$2*(X20-X19)+(1-$Y$2)*Y19 -> -0.12264151 | Z20: =X19+Y19 -> 6179.8838 | AA20: =$C20-Z20 -> -68.283766 | AB20: =ABS(AA20) -> 68.283766 | AC20: =AA20^2 -> 4662.6726 | AD20: =AB20/$C20 -> 0.011172813 | AE20: =$AE$2*(C20/AG16)+(1-$AE$2)*(AE19+AF19) -> 6401.3497 | AF20: =$AF$2*(AE20-AE19)+(1-$AF$2)*AF19 -> 0 | AG20: =$AG$2*(C20/AE20)+(1-$AG$2)*AG16 -> 0.93188764 | AH20: =(AE19+AF19)*AG16 -> 5400.7223 | AI20: =$C20-AH20 -> 710.87766 | AJ20: =ABS(AI20) -> 710.87766 | AK20: =AI20^2 -> 505347.05 | AL20: =AJ20/$C20 -> 0.11631613 | AM20: 6017.5277 | AN20: =$C20-AM20 -> 94.072325 | AO20: =ABS(AN20) -> 94.072325 | AP20: =AN20^2 -> 8849.6023 | AQ20: =AO20/$C20 -> 0.015392422
B21: 2011Q2 | C21: 6905.4 | D21: =AVERAGE(C9,C13,C17) -> 5889.3333 | E21: =$C21-D21 -> 1016.0667 | F21: =ABS(E21) -> 1016.0667 | G21: =E21^2 -> 1032391.5 | H21: =F21/$C21 -> 0.14714088 | I21: =AVERAGE(C17:C20) -> 6144.025 | J21: =$C21-I21 -> 761.375 | K21: =ABS(J21) -> 761.375 | L21: =J21^2 -> 579691.89 | M21: =K21/$C21 -> 0.11025791 | N21: =D21*$N$2+I21*(1-$N$2) -> 6144.025 | O21: =$C21-N21 -> 761.375 | P21: =ABS(O21) -> 761.375 | Q21: =O21^2 -> 579691.89 | R21: =P21/$C21 -> 0.11025791 | S21: =C20*$S$2+S20*(1-$S$2) -> 6139.1664 | T21: =$C21-S21 -> 766.23361 | U21: =ABS(T21) -> 766.23361 | V21: =T21^2 -> 587113.94 | W21: =U21/$C21 -> 0.11096151 | X21: =C21*$X$2+(1-$X$2)*(X20+Y20) -> 6596.9094 | Y21: =$Y$2*(X21-X20)+(1-$Y$2)*Y20 -> -0.12264151 | Z21: =X20+Y20 -> 6138.9615 | AA21: =$C21-Z21 -> 766.43851 | AB21: =ABS(AA21) -> 766.43851 | AC21: =AA21^2 -> 587427.99 | AD21: =AB21/$C21 -> 0.11099118 | AE21: =$AE$2*(C21/AG17)+(1-$AE$2)*(AE20+AF20) -> 6739.3785 | AF21: =$AF$2*(AE21-AE20)+(1-$AF$2)*AF20 -> 0 | AG21: =$AG$2*(C21/AE21)+(1-$AG$2)*AG17 -> 1.0075479 | AH21: =(AE20+AF20)*AG17 -> 6345.719 | AI21: =$C21-AH21 -> 559.68101 | AJ21: =ABS(AI21) -> 559.68101 | AK21: =AI21^2 -> 313242.84 | AL21: =AJ21/$C21 -> 0.08104976 | AM21: 6376.5265 | AN21: =$C21-AM21 -> 528.87353 | AO21: =ABS(AN21) -> 528.87353 | AP21: =AN21^2 -> 279707.21 | AQ21: =AO21/$C21 -> 0.076588399
B22: 2011Q3 | C22: 7166.3 | D22: =AVERAGE(C10,C14,C18) -> 6206.3 | E22: =$C22-D22 -> 960 | F22: =ABS(E22) -> 960 | G22: =E22^2 -> 921600 | H22: =F22/$C22 -> 0.13396034 | I22: =AVERAGE(C18:C21) -> 6384 | J22: =$C22-I22 -> 782.3 | K22: =ABS(J22) -> 782.3 | L22: =J22^2 -> 611993.29 | M22: =K22/$C22 -> 0.10916372 | N22: =D22*$N$2+I22*(1-$N$2) -> 6384 | O22: =$C22-N22 -> 782.3 | P22: =ABS(O22) -> 782.3 | Q22: =O22^2 -> 611993.29 | R22: =P22/$C22 -> 0.10916372 | S22: =C21*$S$2+S21*(1-$S$2) -> 6597.002 | T22: =$C22-S22 -> 569.29795 | U22: =ABS(T22) -> 569.29795 | V22: =T22^2 -> 324100.16 | W22: =U22/$C22 -> 0.079440988 | X22: =C22*$X$2+(1-$X$2)*(X21+Y21) -> 6937.0716 | Y22: =$Y$2*(X22-X21)+(1-$Y$2)*Y21 -> -0.12264151 | Z22: =X21+Y21 -> 6596.7868 | AA22: =$C22-Z22 -> 569.51322 | AB22: =ABS(AA22) -> 569.51322 | AC22: =AA22^2 -> 324345.31 | AD22: =AB22/$C22 -> 0.079471027 | AE22: =$AE$2*(C22/AG18)+(1-$AE$2)*(AE21+AF21) -> 6749.8267 | AF22: =$AF$2*(AE22-AE21)+(1-$AF$2)*AF21 -> 0 | AG22: =$AG$2*(C22/AE22)+(1-$AG$2)*AG18 -> 1.0611372 | AH22: =(AE21+AF21)*AG18 -> 7147.7915 | AI22: =$C22-AH22 -> 18.508499 | AJ22: =ABS(AI22) -> 18.508499 | AK22: =AI22^2 -> 342.56453 | AL22: =AJ22/$C22 -> 0.0025827134 | AM22: 7279.2513 | AN22: =$C22-AM22 -> -112.95125 | AO22: =ABS(AN22) -> 112.95125 | AP22: =AN22^2 -> 12757.985 | AQ22: =AO22/$C22 -> 0.015761446
B23: 2011Q4 | C23: 6822.7 | D23: =AVERAGE(C11,C15,C19) -> 5917.5 | E23: =$C23-D23 -> 905.2 | F23: =ABS(E23) -> 905.2 | G23: =E23^2 -> 819387.04 | H23: =F23/$C23 -> 0.13267475 | I23: =AVERAGE(C19:C22) -> 6599.35 | J23: =$C23-I23 -> 223.35 | K23: =ABS(J23) -> 223.35 | L23: =J23^2 -> 49885.223 | M23: =K23/$C23 -> 0.032736307 | N23: =D23*$N$2+I23*(1-$N$2) -> 6599.35 | O23: =$C23-N23 -> 223.35 | P23: =ABS(O23) -> 223.35 | Q23: =O23^2 -> 49885.223 | R23: =P23/$C23 -> 0.032736307 | S23: =C22*$S$2+S22*(1-$S$2) -> 6937.1658 | T23: =$C23-S23 -> -114.4658 | U23: =ABS(T23) -> 114.4658 | V23: =T23^2 -> 13102.42 | W23: =U23/$C23 -> 0.0167772 | X23: =C23*$X$2+(1-$X$2)*(X22+Y22) -> 6868.6851 | Y23: =$Y$2*(X23-X22)+(1-$Y$2)*Y22 -> -0.12264151 | Z23: =X22+Y22 -> 6936.949 | AA23: =$C23-Z23 -> -114.24897 | AB23: =ABS(AA23) -> 114.24897 | AC23: =AA23^2 -> 13052.828 | AD23: =AB23/$C23 -> 0.016745419 | AE23: =$AE$2*(C23/AG19)+(1-$AE$2)*(AE22+AF22) -> 6602.9335 | AF23: =$AF$2*(AE23-AE22)+(1-$AF$2)*AF22 -> 0 | AG23: =$AG$2*(C23/AE23)+(1-$AG$2)*AG19 -> 1.0413022 | AH23: =(AE22+AF22)*AG19 -> 7080.0492 | AI23: =$C23-AH23 -> -257.34923 | AJ23: =ABS(AI23) -> 257.34923 | AK23: =AI23^2 -> 66228.624 | AL23: =AJ23/$C23 -> 0.037719558 | AM23: 7122.7129 | AN23: =$C23-AM23 -> -300.01289 | AO23: =ABS(AN23) -> 300.01289 | AP23: =AN23^2 -> 90007.737 | AQ23: =AO23/$C23 -> 0.043972752
B24: 2012Q1 | C24: 6546.6 | D24: =AVERAGE(C12,C16,C20) -> 5599.7 | E24: =$C24-D24 -> 946.9 | F24: =ABS(E24) -> 946.9 | G24: =E24^2 -> 896619.61 | H24: =F24/$C24 -> 0.14463997 | I24: =AVERAGE(C20:C23) -> 6751.5 | J24: =$C24-I24 -> -204.9 | K24: =ABS(J24) -> 204.9 | L24: =J24^2 -> 41984.01 | M24: =K24/$C24 -> 0.031298689 | N24: =D24*$N$2+I24*(1-$N$2) -> 6751.5 | O24: =$C24-N24 -> -204.9 | P24: =ABS(O24) -> 204.9 | Q24: =O24^2 -> 41984.01 | R24: =P24/$C24 -> 0.031298689 | S24: =C23*$S$2+S23*(1-$S$2) -> 6868.7708 | T24: =$C24-S24 -> -322.17083 | U24: =ABS(T24) -> 322.17083 | V24: =T24^2 -> 103794.04 | W24: =U24/$C24 -> 0.049211932 | X24: =C24*$X$2+(1-$X$2)*(X23+Y23) -> 6676.1895 | Y24: =$Y$2*(X24-X23)+(1-$Y$2)*Y23 -> -0.12264151 | Z24: =X23+Y23 -> 6868.5624 | AA24: =$C24-Z24 -> -321.96243 | AB24: =ABS(AA24) -> 321.96243 | AC24: =AA24^2 -> 103659.81 | AD24: =AB24/$C24 -> 0.049180098 | AE24: =$AE$2*(C24/AG20)+(1-$AE$2)*(AE23+AF23) -> 6855.6898 | AF24: =$AF$2*(AE24-AE23)+(1-$AF$2)*AF23 -> 0 | AG24: =$AG$2*(C24/AE24)+(1-$AG$2)*AG20 -> 0.9431082 | AH24: =(AE23+AF23)*AG20 -> 6153.1921 | AI24: =$C24-AH24 -> 393.40786 | AJ24: =ABS(AI24) -> 393.40786 | AK24: =AI24^2 -> 154769.74 | AL24: =AJ24/$C24 -> 0.060093462 | AM24: 6712.8575 | AN24: =$C24-AM24 -> -166.2575 | AO24: =ABS(AN24) -> 166.2575 | AP24: =AN24^2 -> 27641.558 | AQ24: =AO24/$C24 -> 0.025396008
B25: 2012Q2 | C25: 6915.9 | D25: =AVERAGE(C13,C17,C21) -> 6166.0333 | E25: =$C25-D25 -> 749.86667 | F25: =ABS(E25) -> 749.86667 | G25: =E25^2 -> 562300.02 | H25: =F25/$C25 -> 0.10842648 | I25: =AVERAGE(C21:C24) -> 6860.25 | J25: =$C25-I25 -> 55.65 | K25: =ABS(J25) -> 55.65 | L25: =J25^2 -> 3096.9225 | M25: =K25/$C25 -> 0.0080466751 | N25: =D25*$N$2+I25*(1-$N$2) -> 6860.25 | O25: =$C25-N25 -> 55.65 | P25: =ABS(O25) -> 55.65 | Q25: =O25^2 -> 3096.9225 | R25: =P25/$C25 -> 0.0080466751 | S25: =C24*$S$2+S24*(1-$S$2) -> 6676.2691 | T25: =$C25-S25 -> 239.6309 | U25: =ABS(T25) -> 239.6309 | V25: =T25^2 -> 57422.967 | W25: =U25/$C25 -> 0.034649272 | X25: =C25*$X$2+(1-$X$2)*(X24+Y24) -> 6819.3674 | Y25: =$Y$2*(X25-X24)+(1-$Y$2)*Y24 -> -0.12264151 | Z25: =X24+Y24 -> 6676.0669 | AA25: =$C25-Z25 -> 239.83315 | AB25: =ABS(AA25) -> 239.83315 | AC25: =AA25^2 -> 57519.94 | AD25: =AB25/$C25 -> 0.034678516 | AE25: =$AE$2*(C25/AG21)+(1-$AE$2)*(AE24+AF24) -> 6860.7193 | AF25: =$AF$2*(AE25-AE24)+(1-$AF$2)*AF24 -> 0 | AG25: =$AG$2*(C25/AE25)+(1-$AG$2)*AG21 -> 1.0077892 | AH25: =(AE24+AF24)*AG21 -> 6907.4362 | AI25: =$C25-AH25 -> 8.4638208 | AJ25: =ABS(AI25) -> 8.4638208 | AK25: =AI25^2 -> 71.636262 | AL25: =AJ25/$C25 -> 0.0012238206 | AM25: 6961.1541 | AN25: =$C25-AM25 -> -45.254058 | AO25: =ABS(AN25) -> 45.254058 | AP25: =AN25^2 -> 2047.9298 | AQ25: =AO25/$C25 -> 0.0065434807
B26: 2012Q3 | C26: 7152.4 | D26: =AVERAGE(C14,C18,C22) -> 6505.9667 | E26: =$C26-D26 -> 646.43333 | F26: =ABS(E26) -> 646.43333 | G26: =E26^2 -> 417876.05 | H26: =F26/$C26 -> 0.090379919 | I26: =AVERAGE(C22:C25) -> 6862.875 | J26: =$C26-I26 -> 289.525 | K26: =ABS(J26) -> 289.525 | L26: =J26^2 -> 83824.726 | M26: =K26/$C26 -> 0.040479419 | N26: =D26*$N$2+I26*(1-$N$2) -> 6862.875 | O26: =$C26-N26 -> 289.525 | P26: =ABS(O26) -> 289.525 | Q26: =O26^2 -> 83824.726 | R26: =P26/$C26 -> 0.040479419 | S26: =C25*$S$2+S25*(1-$S$2) -> 6819.452 | T26: =$C26-S26 -> 332.94797 | U26: =ABS(T26) -> 332.94797 | V26: =T26^2 -> 110854.35 | W26: =U26/$C26 -> 0.046550525 | X26: =C26*$X$2+(1-$X$2)*(X25+Y25) -> 7018.3054 | Y26: =$Y$2*(X26-X25)+(1-$Y$2)*Y25 -> -0.12264151 | Z26: =X25+Y25 -> 6819.2448 | AA26: =$C26-Z26 -> 333.1552 | AB26: =ABS(AA26) -> 333.1552 | AC26: =AA26^2 -> 110992.38 | AD26: =AB26/$C26 -> 0.046579497 | AE26: =$AE$2*(C26/AG22)+(1-$AE$2)*(AE25+AF25) -> 6788.6318 | AF26: =$AF$2*(AE26-AE25)+(1-$AF$2)*AF25 -> 0 | AG26: =$AG$2*(C26/AE26)+(1-$AG$2)*AG22 -> 1.0574571 | AH26: =(AE25+AF25)*AG22 -> 7280.1641 | AI26: =$C26-AH26 -> -127.76414 | AJ26: =ABS(AI26) -> 127.76414 | AK26: =AI26^2 -> 16323.677 | AL26: =AJ26/$C26 -> 0.017863115 | AM26: 7372.9763 | AN26: =$C26-AM26 -> -220.57629 | AO26: =ABS(AN26) -> 220.57629 | AP26: =AN26^2 -> 48653.898 | AQ26: =AO26/$C26 -> 0.030839478
B27: 2012Q4 | C27: 6952.1 | D27: =AVERAGE(C15,C19,C23) -> 6336.7333 | E27: =$C27-D27 -> 615.36667 | F27: =ABS(E27) -> 615.36667 | G27: =E27^2 -> 378676.13 | H27: =F27/$C27 -> 0.088515221 | I27: =AVERAGE(C23:C26) -> 6859.4 | J27: =$C27-I27 -> 92.7 | K27: =ABS(J27) -> 92.7 | L27: =J27^2 -> 8593.29 | M27: =K27/$C27 -> 0.0133341 | N27: =D27*$N$2+I27*(1-$N$2) -> 6859.4 | O27: =$C27-N27 -> 92.7 | P27: =ABS(O27) -> 92.7 | Q27: =O27^2 -> 8593.29 | R27: =P27/$C27 -> 0.0133341 | S27: =C26*$S$2+S26*(1-$S$2) -> 7018.3933 | T27: =$C27-S27 -> -66.293253 | U27: =ABS(T27) -> 66.293253 | V27: =T27^2 -> 4394.7954 | W27: =U27/$C27 -> 0.0095357163 | X27: =C27*$X$2+(1-$X$2)*(X26+Y26) -> 6978.6982 | Y27: =$Y$2*(X27-X26)+(1-$Y$2)*Y26 -> -0.12264151 | Z27: =X26+Y26 -> 7018.1828 | AA27: =$C27-Z27 -> -66.082793 | AB27: =ABS(AA27) -> 66.082793 | AC27: =AA27^2 -> 4366.9355 | AD27: =AB27/$C27 -> 0.0095054433 | AE27: =$AE$2*(C27/AG23)+(1-$AE$2)*(AE26+AF26) -> 6721.408 | AF27: =$AF$2*(AE27-AE26)+(1-$AF$2)*AF26 -> 0 | AG27: =$AG$2*(C27/AE27)+(1-$AG$2)*AG23 -> 1.0379009 | AH27: =(AE26+AF26)*AG23 -> 7069.017 | AI27: =$C27-AH27 -> -116.917 | AJ27: =ABS(AI27) -> 116.917 | AK27: =AI27^2 -> 13669.585 | AL27: =AJ27/$C27 -> 0.016817508 | AM27: 7047.6662 | AN27: =$C27-AM27 -> -95.566244 | AO27: =ABS(AN27) -> 95.566244 | AP27: =AN27^2 -> 9132.9071 | AQ27: =AO27/$C27 -> 0.013746385
B28: 2013Q1 | C28: 6605.3 | D28: =AVERAGE(C16,C20,C24) -> 6089.4333 | E28: =$C28-D28 -> 515.86667 | F28: =ABS(E28) -> 515.86667 | G28: =E28^2 -> 266118.42 | H28: =F28/$C28 -> 0.0780989 | I28: =AVERAGE(C24:C27) -> 6891.75 | J28: =$C28-I28 -> -286.45 | K28: =ABS(J28) -> 286.45 | L28: =J28^2 -> 82053.602 | M28: =K28/$C28 -> 0.04336669 | N28: =D28*$N$2+I28*(1-$N$2) -> 6891.75 | O28: =$C28-N28 -> -286.45 | P28: =ABS(O28) -> 286.45 | Q28: =O28^2 -> 82053.602 | R28: =P28/$C28 -> 0.04336669 | S28: =C27*$S$2+S27*(1-$S$2) -> 6978.7821 | T28: =$C28-S28 -> -373.48208 | U28: =ABS(T28) -> 373.48208 | V28: =T28^2 -> 139488.86 | W28: =U28/$C28 -> 0.056542788 | X28: =C28*$X$2+(1-$X$2)*(X27+Y27) -> 6755.543 | Y28: =$Y$2*(X28-X27)+(1-$Y$2)*Y27 -> -0.12264151 | Z28: =X27+Y27 -> 6978.5756 | AA28: =$C28-Z28 -> -373.2756 | AB28: =ABS(AA28) -> 373.2756 | AC28: =AA28^2 -> 139334.68 | AD28: =AB28/$C28 -> 0.056511529 | AE28: =$AE$2*(C28/AG24)+(1-$AE$2)*(AE27+AF27) -> 6890.4551 | AF28: =$AF$2*(AE28-AE27)+(1-$AF$2)*AF27 -> 0 | AG28: =$AG$2*(C28/AE28)+(1-$AG$2)*AG24 -> 0.95066471 | AH28: =(AE27+AF27)*AG24 -> 6339.0149 | AI28: =$C28-AH28 -> 266.28505 | AJ28: =ABS(AI28) -> 266.28505 | AK28: =AI28^2 -> 70907.73 | AL28: =AJ28/$C28 -> 0.040313847 | AM28: 6763.4827 | AN28: =$C28-AM28 -> -158.18269 | AO28: =ABS(AN28) -> 158.18269 | AP28: =AN28^2 -> 25021.763 | AQ28: =AO28/$C28 -> 0.023947843
... B67: 2022Q4 | C67: 5966.9 | D67: =AVERAGE(C55,C59,C63) -> 5557.4 | E67: =$C67-D67 -> 409.5 | F67: =ABS(E67) -> 409.5 | G67: =E67^2 -> 167690.25 | H67: =F67/$C67 -> 0.068628601 | I67: =AVERAGE(C63:C66) -> 5816.325 | J67: =$C67-I67 -> 150.575 | K67: =ABS(J67) -> 150.575 | L67: =J67^2 -> 22672.831 | M67: =K67/$C67 -> 0.025235047 | N67: =D67*$N$2+I67*(1-$N$2) -> 5816.325 | O67: =$C67-N67 -> 150.575 | P67: =ABS(O67) -> 150.575 | Q67: =O67^2 -> 22672.831 | R67: =P67/$C67 -> 0.025235047 | S67: =C66*$S$2+S66*(1-$S$2) -> 5822.6451 | T67: =$C67-S67 -> 144.25494 | U67: =ABS(T67) -> 144.25494 | V67: =T67^2 -> 20809.488 | W67: =U67/$C67 -> 0.02417586 | X67: =C67*$X$2+(1-$X$2)*(X66+Y66) -> 5908.7546 | Y67: =$Y$2*(X67-X66)+(1-$Y$2)*Y66 -> -0.12264151 | Z67: =X66+Y66 -> 5822.4389 | AA67: =$C67-Z67 -> 144.4611 | AB67: =ABS(AA67) -> 144.4611 | AC67: =AA67^2 -> 20869.011 | AD67: =AB67/$C67 -> 0.024210411 | AE67: =$AE$2*(C67/AG63)+(1-$AE$2)*(AE66+AF66) -> 5809.066 | AF67: =$AF$2*(AE67-AE66)+(1-$AF$2)*AF66 -> 0 | AG67: =$AG$2*(C67/AE67)+(1-$AG$2)*AG63 -> 1.0200703 | AH67: =(AE66+AF66)*AG63 -> 5766.4406 | AI67: =$C67-AH67 -> 200.45937 | AJ67: =ABS(AI67) -> 200.45937 | AK67: =AI67^2 -> 40183.958 | AL67: =AJ67/$C67 -> 0.033595228 | AM67: 5823.2905 | AN67: =$C67-AM67 -> 143.60952 | AO67: =ABS(AN67) -> 143.60952 | AP67: =AN67^2 -> 20623.695 | AQ67: =AO67/$C67 -> 0.024067694
E68: Average | F68: =AVERAGE(F16:F67) -> 587.83141 | G68: =SQRT(AVERAGE(G16:G67)) -> 665.17338 | H68: =AVERAGE(H16:H67) -> 0.10084275 | J68: Average | K68: =AVERAGE(K16:K67) -> 319.02788 | L68: =SQRT(AVERAGE(L16:L67)) -> 425.69767 | M68: =AVERAGE(M16:M67) -> 0.056219979 | O68: Average | P68: =AVERAGE(P16:P67) -> 319.02788 | Q68: =SQRT(AVERAGE(Q16:Q67)) -> 425.69767 | R68: =AVERAGE(R16:R67) -> 0.056219979 | T68: Average | U68: =AVERAGE(U16:U67) -> 324.73487 | V68: =SQRT(AVERAGE(V16:V67)) -> 416.9003 | W68: =AVERAGE(W16:W67) -> 0.056445459 | AA68: Average | AB68: =AVERAGE(AB16:AB67) -> 324.73455 | AC68: =SQRT(AVERAGE(AC16:AC67)) -> 416.9001 | AD68: =AVERAGE(AD16:AD67) -> 0.056444224 | AI68: Average | AJ68: =AVERAGE(AJ16:AJ67) -> 240.30444 | AK68: =SQRT(AVERAGE(AK16:AK67)) -> 366.68579 | AL68: =AVERAGE(AL16:AL67) -> 0.043119027 | AN68: Average | AO68: =AVERAGE(AO16:AO67) -> 233.32053 | AP68: =SQRT(AVERAGE(AP16:AP67)) -> 346.7002 | AQ68: =AVERAGE(AQ16:AQ67) -> 0.041397369
A70: Testing | B70: 2023Q1 | C70: 5897.8 | D70: =AVERAGE(C56,C60,C64) -> 5168.2 | E70: =C70-D70 -> 729.6 | F70: =ABS(E70) -> 729.6 | G70: =E70^2 -> 532316.16 | H70: =F70/C70 -> 0.12370715 | I70: =AVERAGE(C64:C67) -> 5805.75 | J70: =$C70-I70 -> 92.05 | K70: =ABS(J70) -> 92.05 | L70: =J70^2 -> 8473.2025 | M70: =K70/$C70 -> 0.015607515 | N70: =D70*$N$2+I70*(1-$N$2) -> 5805.75 | O70: =$C70-N70 -> 92.05 | P70: =ABS(O70) -> 92.05 | Q70: =O70^2 -> 8473.2025 | R70: =P70/$C70 -> 0.015607515 | S70: =C67*$S$2+S67*(1-$S$2) -> 5908.8395 | T70: =$C70-S70 -> -11.039472 | U70: =ABS(T70) -> 11.039472 | V70: =T70^2 -> 121.86993 | W70: =U70/$C70 -> 0.0018717948 | X70: =C70*$X$2+(1-$X$2)*(X67+Y67) -> 5902.1598 | Y70: =$Y$2*(X70-X67)+(1-$Y$2)*Y67 -> -0.12264151 | Z70: =X67+Y67 -> 5908.6319 | AA70: =$C70-Z70 -> -10.831938 | AB70: =ABS(AA70) -> 10.831938 | AC70: =AA70^2 -> 117.33088 | AD70: =AB70/$C70 -> 0.0018366065 | AE70: =$AE$2*(C70/AG64)+(1-$AE$2)*(AE67+AF67) -> 6065.6347 | AF70: =$AF$2*(AE70-AE67)+(1-$AF$2)*AF67 -> 0 | AG70: =$AG$2*(C70/AE70)+(1-$AG$2)*AG64 -> 0.95858626 | AH70: =(AE67+AF67)*AG64 -> 5492.6145 | AI70: =$C70-AH70 -> 405.18552 | AJ70: =ABS(AI70) -> 405.18552 | AK70: =AI70^2 -> 164175.3 | AL70: =AJ70/$C70 -> 0.068701129 | AM70: 5541.2643 | AN70: =$C70-AM70 -> 356.5357 | AO70: =ABS(AN70) -> 356.5357 | AP70: =AN70^2 -> 127117.7 | AQ70: =AO70/$C70 -> 0.060452321
B71: 2023Q2 | C71: 6497.5 | D71: =AVERAGE(C57,C61,C65) -> 5122.6 | E71: =C71-D71 -> 1374.9 | F71: =ABS(E71) -> 1374.9 | G71: =E71^2 -> 1890350 | H71: =F71/C71 -> 0.21160446 | I71: =AVERAGE(C65:C70) -> 5863.8 | J71: =$C71-I71 -> 633.7 | K71: =ABS(J71) -> 633.7 | L71: =J71^2 -> 401575.69 | M71: =K71/$C71 -> 0.097529819 | N71: =D71*$N$2+I71*(1-$N$2) -> 5863.8 | O71: =$C71-N71 -> 633.7 | P71: =ABS(O71) -> 633.7 | Q71: =O71^2 -> 401575.69 | R71: =P71/$C71 -> 0.097529819 | S71: =C70*$S$2+S70*(1-$S$2) -> 5902.2432 | T71: =$C71-S71 -> 595.25677 | U71: =ABS(T71) -> 595.25677 | V71: =T71^2 -> 354330.62 | W71: =U71/$C71 -> 0.091613201 | X71: =C71*$X$2+(1-$X$2)*(X70+Y70) -> 6257.8269 | Y71: =$Y$2*(X71-X70)+(1-$Y$2)*Y70 -> -0.12264151 | Z71: =X70+Y70 -> 5902.0372 | AA71: =$C71-Z71 -> 595.4628 | AB71: =ABS(AA71) -> 595.4628 | AC71: =AA71^2 -> 354575.95 | AD71: =AB71/$C71 -> 0.09164491 | AE71: =$AE$2*(C71/AG65)+(1-$AE$2)*(AE70+AF70) -> 6451.1029 | AF71: =$AF$2*(AE71-AE70)+(1-$AF$2)*AF70 -> 0 | AG71: =$AG$2*(C71/AE71)+(1-$AG$2)*AG65 -> 0.98730711 | AH71: =(AE70+AF70)*AG65 -> 5874.0165 | AI71: =$C71-AH71 -> 623.48355 | AJ71: =ABS(AI71) -> 623.48355 | AK71: =AI71^2 -> 388731.73 | AL71: =AJ71/$C71 -> 0.095957452 | AM71: 6047.0041 | AN71: =$C71-AM71 -> 450.4959 | AO71: =ABS(AN71) -> 450.4959 | AP71: =AN71^2 -> 202946.56 | AQ71: =AO71/$C71 -> 0.069333728
B72: 2023Q3 | C72: 6692.2 | D72: =AVERAGE(C58,C62,C66) -> 5830.5 | E72: =C72-D72 -> 861.7 | F72: =ABS(E72) -> 861.7 | G72: =E72^2 -> 742526.89 | H72: =F72/C72 -> 0.12876184 | I72: =AVERAGE(C66:C71) -> 6058.575 | J72: =$C72-I72 -> 633.625 | K72: =ABS(J72) -> 633.625 | L72: =J72^2 -> 401480.64 | M72: =K72/$C72 -> 0.094681121 | N72: =D72*$N$2+I72*(1-$N$2) -> 6058.575 | O72: =$C72-N72 -> 633.625 | P72: =ABS(O72) -> 633.625 | Q72: =O72^2 -> 401480.64 | R72: =P72/$C72 -> 0.094681121 | S72: =C71*$S$2+S71*(1-$S$2) -> 6257.9178 | T72: =$C72-S72 -> 434.28225 | U72: =ABS(T72) -> 434.28225 | V72: =T72^2 -> 188601.07 | W72: =U72/$C72 -> 0.064893794 | X72: =C72*$X$2+(1-$X$2)*(X71+Y71) -> 6517.316 | Y72: =$Y$2*(X72-X71)+(1-$Y$2)*Y71 -> -0.12264151 | Z72: =X71+Y71 -> 6257.7043 | AA72: =$C72-Z72 -> 434.4957 | AB72: =ABS(AA72) -> 434.4957 | AC72: =AA72^2 -> 188786.52 | AD72: =AB72/$C72 -> 0.06492569 | AE72: =$AE$2*(C72/AG66)+(1-$AE$2)*(AE71+AF71) -> 6416.6433 | AF72: =$AF$2*(AE72-AE71)+(1-$AF$2)*AF71 -> 0 | AG72: =$AG$2*(C72/AE72)+(1-$AG$2)*AG66 -> 1.0448758 | AH72: =(AE71+AF71)*AG66 -> 6752.4442 | AI72: =$C72-AH72 -> -60.244241 | AJ72: =ABS(AI72) -> 60.244241 | AK72: =AI72^2 -> 3629.3685 | AL72: =AJ72/$C72 -> 0.0090021578 | AM72: 6964.4303 | AN72: =$C72-AM72 -> -272.23027 | AO72: =ABS(AN72) -> 272.23027 | AP72: =AN72^2 -> 74109.321 | AQ72: =AO72/$C72 -> 0.040678741
B73: 2023Q4 | C73: 6406.5 | D73: =AVERAGE(C59,C63,C67) -> 5763.3667 | E73: =C73-D73 -> 643.13333 | F73: =ABS(E73) -> 643.13333 | G73: =E73^2 -> 413620.48 | H73: =F73/C73 -> 0.10038763 | I73: =AVERAGE(C67:C72) -> 6263.6 | J73: =$C73-I73 -> 142.9 | K73: =ABS(J73) -> 142.9 | L73: =J73^2 -> 20420.41 | M73: =K73/$C73 -> 0.022305471 | N73: =D73*$N$2+I73*(1-$N$2) -> 6263.6 | O73: =$C73-N73 -> 142.9 | P73: =ABS(O73) -> 142.9 | Q73: =O73^2 -> 20420.41 | R73: =P73/$C73 -> 0.022305471 | S73: =C72*$S$2+S72*(1-$S$2) -> 6517.4077 | T73: =$C73-S73 -> -110.90767 | U73: =ABS(T73) -> 110.90767 | V73: =T73^2 -> 12300.512 | W73: =U73/$C73 -> 0.017311742 | X73: =C73*$X$2+(1-$X$2)*(X72+Y72) -> 6451.0539 | Y73: =$Y$2*(X73-X72)+(1-$Y$2)*Y72 -> -0.12264151 | Z73: =X72+Y72 -> 6517.1934 | AA73: =$C73-Z73 -> -110.69336 | AB73: =ABS(AA73) -> 110.69336 | AC73: =AA73^2 -> 12253.02 | AD73: =AB73/$C73 -> 0.017278289 | AE73: =$AE$2*(C73/AG67)+(1-$AE$2)*(AE72+AF72) -> 6335.1014 | AF73: =$AF$2*(AE73-AE72)+(1-$AF$2)*AF72 -> 0 | AG73: =$AG$2*(C73/AE73)+(1-$AG$2)*AG67 -> 1.0157823 | AH73: =(AE72+AF72)*AG67 -> 6545.4275 | AI73: =$C73-AH73 -> -138.92748 | AJ73: =ABS(AI73) -> 138.92748 | AK73: =AI73^2 -> 19300.845 | AL73: =AJ73/$C73 -> 0.021685395 | AM73: 6605.1586 | AN73: =$C73-AM73 -> -198.65861 | AO73: =ABS(AN73) -> 198.65861 | AP73: =AN73^2 -> 39465.242 | AQ73: =AO73/$C73 -> 0.031008914
B74: 2024Q1 | C74: 6169 | D74: =AVERAGE(C60,C64,C70) -> 5562.6667 | E74: =C74-D74 -> 606.33333 | F74: =ABS(E74) -> 606.33333 | G74: =E74^2 -> 367640.11 | H74: =F74/C74 -> 0.098287135 | I74: =AVERAGE(C70:C73) -> 6373.5 | J74: =$C74-I74 -> -204.5 | K74: =ABS(J74) -> 204.5 | L74: =J74^2 -> 41820.25 | M74: =K74/$C74 -> 0.033149619 | N74: =D74*$N$2+I74*(1-$N$2) -> 6373.5 | O74: =$C74-N74 -> -204.5 | P74: =ABS(O74) -> 204.5 | Q74: =O74^2 -> 41820.25 | R74: =P74/$C74 -> 0.033149619 | S74: =C73*$S$2+S73*(1-$S$2) -> 6451.1387 | T74: =$C74-S74 -> -282.13874 | U74: =ABS(T74) -> 282.13874 | V74: =T74^2 -> 79602.266 | W74: =U74/$C74 -> 0.045734922 | X74: =C74*$X$2+(1-$X$2)*(X73+Y73) -> 6282.477 | Y74: =$Y$2*(X74-X73)+(1-$Y$2)*Y73 -> -0.12264151 | Z74: =X73+Y73 -> 6450.9313 | AA74: =$C74-Z74 -> -281.9313 | AB74: =ABS(AA74) -> 281.9313 | AC74: =AA74^2 -> 79485.26 | AD74: =AB74/$C74 -> 0.045701297 | AE74: =$AE$2*(C74/AG70)+(1-$AE$2)*(AE73+AF73) -> 6395.2232 | AF74: =$AF$2*(AE74-AE73)+(1-$AF$2)*AF73 -> 0 | AG74: =$AG$2*(C74/AE74)+(1-$AG$2)*AG70 -> 0.96152937 | AH74: =(AE73+AF73)*AG70 -> 6072.7412 | AI74: =$C74-AH74 -> 96.258848 | AJ74: =ABS(AI74) -> 96.258848 | AK74: =AI74^2 -> 9265.7658 | AL74: =AJ74/$C74 -> 0.015603639 | AM74: 5992.5428 | AN74: =$C74-AM74 -> 176.45723 | AO74: =ABS(AN74) -> 176.45723 | AP74: =AN74^2 -> 31137.153 | AQ74: =AO74/$C74 -> 0.028603862
B75: 2024Q2 | C75: 6490 | D75: =AVERAGE(C61,C65,C71) -> 6034.6 | E75: =C75-D75 -> 455.4 | F75: =ABS(E75) -> 455.4 | G75: =E75^2 -> 207389.16 | H75: =F75/C75 -> 0.070169492 | I75: =AVERAGE(C71:C74) -> 6441.3 | J75: =$C75-I75 -> 48.7 | K75: =ABS(J75) -> 48.7 | L75: =J75^2 -> 2371.69 | M75: =K75/$C75 -> 0.0075038521 | N75: =D75*$N$2+I75*(1-$N$2) -> 6441.3 | O75: =$C75-N75 -> 48.7 | P75: =ABS(O75) -> 48.7 | Q75: =O75^2 -> 2371.69 | R75: =P75/$C75 -> 0.0075038521 | S75: =C74*$S$2+S74*(1-$S$2) -> 6282.5568 | T75: =$C75-S75 -> 207.44324 | U75: =ABS(T75) -> 207.44324 | V75: =T75^2 -> 43032.697 | W75: =U75/$C75 -> 0.031963519 | X75: =C75*$X$2+(1-$X$2)*(X74+Y74) -> 6406.4229 | Y75: =$Y$2*(X75-X74)+(1-$Y$2)*Y74 -> -0.12264151 | Z75: =X74+Y74 -> 6282.3544 | AA75: =$C75-Z75 -> 207.64563 | AB75: =ABS(AA75) -> 207.64563 | AC75: =AA75^2 -> 43116.708 | AD75: =AB75/$C75 -> 0.031994704 | AE75: =$AE$2*(C75/AG71)+(1-$AE$2)*(AE74+AF74) -> 6501.9224 | AF75: =$AF$2*(AE75-AE74)+(1-$AF$2)*AF74 -> 0 | AG75: =$AG$2*(C75/AE75)+(1-$AG$2)*AG71 -> 0.99259852 | AH75: =(AE74+AF74)*AG71 -> 6314.0493 | AI75: =$C75-AH75 -> 175.95067 | AJ75: =ABS(AI75) -> 175.95067 | AK75: =AI75^2 -> 30958.639 | AL75: =AJ75/$C75 -> 0.027111044 | AM75: 6287.1575 | AN75: =$C75-AM75 -> 202.84253 | AO75: =ABS(AN75) -> 202.84253 | AP75: =AN75^2 -> 41145.092 | AQ75: =AO75/$C75 -> 0.031254627
B76: 2024Q3 | C76: 6873 | D76: =AVERAGE(C62,C66,C72) -> 6255.2 | E76: =C76-D76 -> 617.8 | F76: =ABS(E76) -> 617.8 | G76: =E76^2 -> 381676.84 | H76: =F76/C76 -> 0.089887967 | I76: =AVERAGE(C72:C75) -> 6439.425 | J76: =$C76-I76 -> 433.575 | K76: =ABS(J76) -> 433.575 | L76: =J76^2 -> 187987.28 | M76: =K76/$C76 -> 0.063083806 | N76: =D76*$N$2+I76*(1-$N$2) -> 6439.425 | O76: =$C76-N76 -> 433.575 | P76: =ABS(O76) -> 433.575 | Q76: =O76^2 -> 187987.28 | R76: =P76/$C76 -> 0.063083806 | S76: =C75*$S$2+S75*(1-$S$2) -> 6406.5071 | T76: =$C76-S76 -> 466.4929 | U76: =ABS(T76) -> 466.4929 | V76: =T76^2 -> 217615.63 | W76: =U76/$C76 -> 0.067873258 | X76: =C76*$X$2+(1-$X$2)*(X75+Y75) -> 6685.1539 | Y76: =$Y$2*(X76-X75)+(1-$Y$2)*Y75 -> -0.12264151 | Z76: =X75+Y75 -> 6406.3002 | AA76: =$C76-Z76 -> 466.69976 | AB76: =ABS(AA76) -> 466.69976 | AC76: =AA76^2 -> 217808.66 | AD76: =AB76/$C76 -> 0.067903355 | AE76: =$AE$2*(C76/AG72)+(1-$AE$2)*(AE75+AF75) -> 6547.361 | AF76: =$AF$2*(AE76-AE75)+(1-$AF$2)*AF75 -> 0 | AG76: =$AG$2*(C76/AE76)+(1-$AG$2)*AG72 -> 1.047244 | AH76: =(AE75+AF75)*AG72 -> 6793.7012 | AI76: =$C76-AH76 -> 79.29877 | AJ76: =ABS(AI76) -> 79.29877 | AK76: =AI76^2 -> 6288.2949 | AL76: =AJ76/$C76 -> 0.011537723 | AM76: 6965.3533 | AN76: =$C76-AM76 -> -92.35327 | AO76: =ABS(AN76) -> 92.35327 | AP76: =AN76^2 -> 8529.1265 | AQ76: =AO76/$C76 -> 0.013437112
B77: 2024Q4 | C77: 6388 | D77: =AVERAGE(C63,C67,C73) -> 6127.5333 | E77: =C77-D77 -> 260.46667 | F77: =ABS(E77) -> 260.46667 | G77: =E77^2 -> 67842.884 | H77: =F77/C77 -> 0.040774369 | I77: =AVERAGE(C73:C76) -> 6484.625 | J77: =$C77-I77 -> -96.625 | K77: =ABS(J77) -> 96.625 | L77: =J77^2 -> 9336.3906 | M77: =K77/$C77 -> 0.015126018 | N77: =D77*$N$2+I77*(1-$N$2) -> 6484.625 | O77: =$C77-N77 -> -96.625 | P77: =ABS(O77) -> 96.625 | Q77: =O77^2 -> 9336.3906 | R77: =P77/$C77 -> 0.015126018 | S77: =C76*$S$2+S76*(1-$S$2) -> 6685.2433 | T77: =$C77-S77 -> -297.24335 | U77: =ABS(T77) -> 297.24335 | V77: =T77^2 -> 88353.608 | W77: =U77/$C77 -> 0.04653152 | X77: =C77*$X$2+(1-$X$2)*(X76+Y76) -> 6507.5547 | Y77: =$Y$2*(X77-X76)+(1-$Y$2)*Y76 -> -0.12264151 | Z77: =X76+Y76 -> 6685.0313 | AA77: =$C77-Z77 -> -297.03127 | AB77: =ABS(AA77) -> 297.03127 | AC77: =AA77^2 -> 88227.573 | AD77: =AB77/$C77 -> 0.04649832 | AE77: =$AE$2*(C77/AG73)+(1-$AE$2)*(AE76+AF76) -> 6392.5252 | AF77: =$AF$2*(AE77-AE76)+(1-$AF$2)*AF76 -> 0 | AG77: =$AG$2*(C77/AE77)+(1-$AG$2)*AG73 -> 1.0077471 | AH77: =(AE76+AF76)*AG73 -> 6650.6935 | AI77: =$C77-AH77 -> -262.69347 | AJ77: =ABS(AI77) -> 262.69347 | AK77: =AI77^2 -> 69007.861 | AL77: =AJ77/$C77 -> 0.041122961 | AM77: 6812.8168 | AN77: =$C77-AM77 -> -424.81676 | AO77: =ABS(AN77) -> 424.81676 | AP77: =AN77^2 -> 180469.28 | AQ77: =AO77/$C77 -> 0.066502311
E78: Average | F78: =AVERAGE(F70:F77) -> 693.66667 | G78: =SQRT(AVERAGE(G70:G77)) -> 758.56464 | H78: =AVERAGE(H70:H77) -> 0.1079475 | J78: Average | K78: =AVERAGE(K70:K77) -> 285.70937 | L78: =SQRT(AVERAGE(L70:L77)) -> 366.31024 | M78: =AVERAGE(M70:M77) -> 0.043623403 | O78: Average | P78: =AVERAGE(P70:P77) -> 285.70937 | Q78: =SQRT(AVERAGE(Q70:Q77)) -> 366.31024 | R78: =AVERAGE(R70:R77) -> 0.043623403 | T78: Average | U78: =AVERAGE(U70:U77) -> 300.60055 | V78: =SQRT(AVERAGE(V70:V77)) -> 350.70612 | W78: =AVERAGE(W70:W77) -> 0.045974219 | AA78: Average | AB78: =AVERAGE(AB70:AB77) -> 300.59897 | AC78: =SQRT(AVERAGE(AC70:AC77)) -> 350.77967 | AD78: =AVERAGE(AD70:AD77) -> 0.045972896 | AI78: Average | AJ78: =AVERAGE(AJ70:AJ77) -> 230.25532 | AK78: =SQRT(AVERAGE(AK70:AK77)) -> 293.97232 | AL78: =AVERAGE(AL70:AL77) -> 0.036340187 | AN78: Average | AO78: =AVERAGE(AO70:AO77) -> 271.79878 | AP78: =SQRT(AVERAGE(AP70:AP77)) -> 296.8416 | AQ78: =AVERAGE(AQ70:AQ77) -> 0.042658952
A80: Forecasting | B80: 2025Q1 | AH80: =($AE$77+$AF$77)*AG74 -> 6146.6008
...

Sheet ModelSummary
B2: Model Name | C2: MAE | D2: RMSE | E2: MAPE
B3: MA3_YoY | C3: =RevenueModel!F78 -> 693.66667 | D3: =RevenueModel!G78 -> 758.56464 | E3: =RevenueModel!H78 -> 0.1079475
B4: MA4_Consecutive | C4: =RevenueModel!K78 -> 285.70937 | D4: =RevenueModel!L78 -> 366.31024 | E4: =RevenueModel!M78 -> 0.043623403
B5: MA_Hybrid | C5: =RevenueModel!P78 -> 285.70937 | D5: =RevenueModel!Q78 -> 366.31024 | E5: =RevenueModel!R78 -> 0.043623403
B6: SES | C6: =RevenueModel!U78 -> 300.60055 | D6: =RevenueModel!V78 -> 350.70612 | E6: =RevenueModel!W78 -> 0.045974219
B7: Holt | C7: =RevenueModel!AB78 -> 300.59897 | D7: =RevenueModel!AC78 -> 350.77967 | E7: =RevenueModel!AD78 -> 0.045972896
B8: Holt-Winters | C8: =RevenueModel!AJ78 -> 230.25532 | D8: =RevenueModel!AK78 -> 293.97232 | E8: =RevenueModel!AL78 -> 0.036340187
B9: ARIMA | C9: =RevenueModel!AO78 -> 271.79878 | D9: =RevenueModel!AP78 -> 296.8416 | E9: =RevenueModel!AQ78 -> 0.042658952

Sheet Actual vs. Budget
A1: YearQuarter | B1: Metrics | C1: Actual_Company-operated restaurants | D1: Actual_Franchised restaurants | E1: Actual_Other | F1: Budget_Company-operated restaurants | G1: Budget_Franchised restaurants | H1: Budget_Other
A2: 2010Q1 | B2: 1-Revenues | C2: 3803.1 | D2: 1807 | F2: 3300.31 | G2: 1777.09
A3: 2010Q2 | B3: 1-Revenues | C3: 4013.4 | D3: 1932.1 | F3: 3901.254 | G3: 2100.6752
A4: 2010Q3 | B4: 1-Revenues | C4: 4246.6 | D4: 2058.3 | F4: 4153.7266 | G4: 2236.622
A5: 2010Q4 | B5: 1-Revenues | C5: 4170.2 | D5: 2043.9 | F5: 4070.5232 | G5: 2191.8202
A6: 2011Q1 | B6: 1-Revenues | C6: 4152.7 | D6: 1958.9 | F6: 3510.4695 | G6: 1890.2528
A7: 2011Q2 | B7: 1-Revenues | C7: 4697.4 | D7: 2208 | F7: 4124.7173 | G7: 2221.0016
A8: 2011Q3 | B8: 1-Revenues | C8: 4855.5 | D8: 2310.8 | F8: 4646.0645 | G8: 2501.727
A9: 2011Q4 | B9: 1-Revenues | C9: 4587.2 | D9: 2235.5 | F9: 4602.032 | G9: 2478.0172
A10: 2012Q1 | B10: 1-Revenues | C10: 4432.2 | D10: 2114.4 | F10: 3999.5749 | G10: 2153.6173
A11: 2012Q2 | B11: 1-Revenues | C11: 4673.5 | D11: 2242.4 | F11: 4489.8335 | G11: 2417.6027
A12: 2012Q3 | B12: 1-Revenues | C12: 4838.4 | D12: 2314 | F12: 4732.1067 | G12: 2548.0575
A13: 2012Q4 | B13: 1-Revenues | C13: 4658.4 | D13: 2293.7 | F13: 4594.861 | G13: 2474.1559
... A41: 2019Q4 | B41: 1-Revenues | C41: 2363.3 | D41: 2985.7 | F41: 2626.6096 | G41: 2626.6096
A42: 2020Q1 | B42: 1-Revenues | C42: 2025.8 | D42: 2608 | E42: 80.6 | F42: 2026.839 | G42: 2938.9166 | H42: 101.34195
A43: 2020Q2 | B43: 1-Revenues | C43: 1593.7 | D43: 2088 | E43: 79.8 | F43: 2074.384 | G43: 3007.8569 | H43: 103.7192
A44: 2020Q3 | B44: 1-Revenues | C44: 2286.4 | D44: 3044.8 | E44: 86.9 | F44: 1755.5345 | G44: 2545.5251 | H44: 87.776726
A45: 2020Q4 | B45: 1-Revenues | C45: 2233.1 | D45: 2985.2 | E45: 95.7 | F45: 1946.5906 | G45: 2822.5564 | H45: 97.329529
A46: 2021Q1 | B46: 1-Revenues | C46: 2161.5 | D46: 2877.4 | E46: 85.7 | F46: 1924.9908 | G46: 2791.2367 | H46: 96.249541
A47: 2021Q2 | B47: 1-Revenues | C47: 2488.7 | D47: 3306.2 | E47: 93 | F47: 2027.162 | G47: 2939.3849 | H47: 101.3581
A48: 2021Q3 | B48: 1-Revenues | C48: 2598.4 | D48: 3510.2 | E48: 92.7 | F48: 2503.6281 | G48: 3630.2607 | H48: 125.1814
A49: 2021Q4 | B49: 1-Revenues | C49: 2538.4 | D49: 3391.2 | E49: 79.6 | F49: 2366.9297 | G49: 3432.0481 | H49: 118.34649
A50: 2022Q1 | B50: 1-Revenues | C50: 2302.4 | D50: 3262.8 | E50: 100.4 | F50: 2228.4956 | G50: 3231.3186 | H50: 111.42478
A51: 2022Q2 | B51: 1-Revenues | C51: 2112.8 | D51: 3526.8 | E51: 78.8 | F51: 2319.4668 | G51: 3363.2268 | H51: 115.97334
A52: 2022Q3 | B52: 1-Revenues | C52: 2124.8 | D52: 3671.2 | E52: 76.1 | F52: 2512.8147 | G52: 3643.5813 | H52: 125.64074
A53: 2022Q4 | B53: 1-Revenues | C53: 3247 | D53: 2624.2 | E53: 95.7 | F53: 2306.5763 | G53: 3344.5356 | H53: 115.32881
... A181: 2024Q4 | B181: 3-Operating Income | C181: 333 | D181: 3324 | E181: -789 | F181: 665.06935 | G181: 2660.2774 | H181: -665.06935

Sheet Actual vs. Model
A1: YearQuarter | B1: Actual_Total revenues | C1: Model_Total revenues
A2: 2010Q1 | B2: 5610.1 | C2: 5077.4
A3: 2010Q2 | B3: 5945.5 | C3: 6001.9292
A4: 2010Q3 | B4: 6304.9 | C4: 6390.3486
A5: 2010Q4 | B5: 6214.1 | C5: 6262.3433
A6: 2011Q1 | B6: 6111.6 | C6: 5400.7223
A7: 2011Q2 | B7: 6905.4 | C7: 6345.719
A8: 2011Q3 | B8: 7166.3 | C8: 7147.7915
A9: 2011Q4 | B9: 6822.7 | C9: 7080.0492
A10: 2012Q1 | B10: 6546.6 | C10: 6153.1921
A11: 2012Q2 | B11: 6915.9 | C11: 6907.4362
A12: 2012Q3 | B12: 7152.4 | C12: 7280.1641
A13: 2012Q4 | B13: 6952.1 | C13: 7069.017
... A61: 2024Q4 | B61: 6388 | C61: 6650.6935
